Workbook

Sheet MethodData
A1: Classe.Método | B1: CC | C1: CCM | D1: CDISP | E1: CINT | F1: CND | G1: FDP | H1: HD | I1: HEF | J1: HER | K1: HL | L1: HVC | M1: HVL | N1: LAA | O1: LND | P1: LOC | Q1: MMI | R1: MND | S1: NOAV | T1: NOL | U1: NOPM
A2: Barge: Barge(Compass, IPosition) | B2: 1 | C2: 0 | D2: 0.6 | E2: 5 | F2: 0 | G2: 0 | H2: 6 | I2: 301.1369 | J2: 0.015 | K2: 14 | L2: 12 | M2: 50.1895 | N2: 0 | O2: 0 | P2: 11 | Q2: 65.3869 | R2: 0 | S2: 2 | T2: 0 | U2: 2
A3: BoardWindow: close() | B3: 2 | C3: 1 | D3: 1 | E3: 1 | F3: 1 | G3: 0 | H3: 7.5 | I3: 247.5 | J3: 0.0131 | K3: 11 | L3: 8 | M3: 33 | N3: 1 | O3: 0 | P3: 6 | Q3: 72.2996 | R3: 1 | S3: 1 | T3: 0 | U3: 0
A4: BoardWindow: createBoardPanel(char[][], List<IPosition>) | B4: 10 | C4: 10 | D4: 0.5 | E4: 10 | F4: 2 | G4: 4 | H4: 27.5 | I4: 18919.5 | J4: 0.2367 | K4: 119 | L4: 55 | M4: 687.9818 | N4: 0 | O4: 3 | P4: 43 | Q4: 44.1935 | R4: 5 | S4: 19 | T4: 3 | U4: 2
A5: BoardWindow: show(char[][], char[][], List<IPosition>, List<IPosition>) | B5: 2 | C5: 1 | D5: 0.4545 | E5: 10 | F5: 1 | G5: 4 | H5: 16.7143 | I5: 8124.3706 | J5: 0.1347 | K5: 88 | L5: 46 | M5: 486.0735 | N5: 0.2857 | O5: 0 | P5: 30 | Q5: 48.873 | R5: 1 | S5: 17 | T5: 0 | U5: 4
A6: Caravel: Caravel(Compass, IPosition) | B6: 9 | C6: 5 | D6: 0.5 | E6: 6 | F6: 0 | G6: 1 | H6: 27 | I6: 12198.39 | J6: 0.1766 | K6: 93 | L6: 29 | M6: 451.7922 | N6: 0 | O6: 1 | P6: 27 | Q6: 49.8962 | R6: 1 | S6: 10 | T6: 4 | U6: 2
A7: Carrack: Carrack(Compass, IPosition) | B7: 9 | C7: 5 | D7: 0.5 | E7: 6 | F7: 0 | G7: 1 | H7: 27 | I7: 12198.39 | J7: 0.1766 | K7: 93 | L7: 29 | M7: 451.7922 | N7: 0 | O7: 1 | P7: 27 | Q7: 49.8962 | R7: 1 | S7: 10 | T7: 4 | U7: 2
A8: Compass: Compass(char) | B8: 1 | C8: 0 | D8: 0 | E8: 0 | F8: 0 | G8: 0 | H8: 1 | I8: 8 | J8: 0.0013 | K8: 4 | L8: 4 | M8: 8 | N8: 1 | O8: 0 | P8: 9 | Q8: 72.8607 | R8: 0 | S8: 2 | T8: 0 | U8: 1
A9: Compass: charToCompass(char) | B9: 6 | C9: 1 | D9: 0 | E9: 0 | F9: 0 | G9: 0 | H9: 5.0909 | I9: 615.6326 | J9: 0.0241 | K9: 29 | L9: 18 | M9: 120.9278 | N9: 1 | O9: 0 | P9: 28 | Q9: 53.6323 | R9: 1 | S9: 6 | T9: 0 | U9: 1
A10: Compass: getDirection() | B10: 1 | C10: 0 | D10: 0 | E10: 0 | F10: 0 | G10: 0 | H10: 1.5 | I10: 12 | J10: 0.0017 | K10: 4 | L10: 4 | M10: 8 | N10: 1 | O10: 0 | P10: 9 | Q10: 72.8607 | R10: 0 | S10: 1 | T10: 0 | U10: 0
A11: Compass: randomBearing() | B11: 1 | C11: 0 | D11: 0.5 | E11: 1 | F11: 0 | G11: 1 | H11: 4.6667 | I11: 186.028 | J11: 0.0109 | K11: 12 | L11: 10 | M11: 39.8631 | N11: 0 | O11: 0 | P11: 10 | Q11: 67.0454 | R11: 0 | S11: 3 | T11: 0 | U11: 0
A12: Compass: toString() | B12: 1 | C12: 0 | D12: 0 | E12: 0 | F12: 0 | G12: 0 | H12: 1.5 | I12: 17.4145 | J12: 0.0022 | K12: 5 | L12: 5 | M12: 11.6096 | N12: 1 | O12: 0 | P12: 10 | Q12: 70.8942 | R12: 0 | S12: 1 | T12: 0 | U12: 0
A13: Compass: valueOf(String) | B13: 1 | C13: 0 | D13: 0 | E13: 0 | F13: 0 | G13: 0 | H13: 0 | K13: 0 | L13: 0 | N13: 0 | O13: 0 | P13: 0 | Q13: 0 | R13: -1 | S13: 0 | T13: 0 | U13: 1
A14: Compass: values() | B14: 1 | C14: 0 | D14: 0 | E14: 0 | F14: 0 | G14: 0 | H14: 0 | K14: 0 | L14: 0 | N14: 0 | O14: 0 | P14: 0 | Q14: 0 | R14: -1 | S14: 0 | T14: 0 | U14: 0
A15: Fleet: Fleet() | B15: 1 | C15: 0 | D15: 0 | E15: 0 | F15: 0 | G15: 0 | H15: 1 | I15: 4.7549 | J15: 0.0009 | K15: 3 | L15: 3 | M15: 4.7549 | N15: 1 | O15: 0 | P15: 7 | Q15: 77.3494 | R15: 0 | S15: 1 | T15: 0 | U15: 0
A16: Fleet: addShip(IShip) | B16: 4 | C16: 3 | D16: 0.25 | E16: 2 | F16: 1 | G16: 0 | H16: 10.2857 | I16: 1092.3242 | J16: 0.0354 | K16: 25 | L16: 19 | M16: 106.1982 | N16: 0.5 | O16: 0 | P16: 23 | Q16: 55.9276 | R16: 1 | S16: 4 | T16: 0 | U16: 1
A17: Fleet: colisionRisk(IShip) | B17: 3 | C17: 2 | D17: 0.6667 | E17: 3 | F17: 1 | G17: 0 | H17: 10.2143 | I17: 1103.6352 | J17: 0.0356 | K17: 25 | L17: 20 | M17: 108.0482 | N17: 1 | O17: 1 | P17: 16 | Q17: 59.3475 | R17: 1 | S17: 3 | T17: 1 | U17: 1
A18: Fleet: createRandom() | B18: 4 | C18: 3 | D18: 0.75 | E18: 3 | F18: 1 | G18: 1 | H18: 14.375 | I18: 2597.3573 | J18: 0.063 | K18: 38 | L18: 27 | M18: 180.6857 | N18: 0 | O18: 1 | P18: 27 | Q18: 52.7984 | R18: 2 | S18: 5 | T18: 1 | U18: 0
A19: Fleet: getFloatingShips() | B19: 3 | C19: 2 | D19: 1 | E19: 2 | F19: 1 | G19: 0 | H19: 5.8333 | I19: 232.535 | J19: 0.0126 | K19: 12 | L19: 10 | M19: 39.8631 | N19: 1 | O19: 1 | P19: 19 | Q19: 60.8169 | R19: 0 | S19: 3 | T19: 1 | U19: 0
A20: Fleet: getShips() | B20: 1 | C20: 0 | D20: 0 | E20: 0 | F20: 0 | G20: 0 | H20: 1 | I20: 4.7549 | J20: 0.0009 | K20: 3 | L20: 3 | M20: 4.7549 | N20: 1 | O20: 0 | P20: 10 | Q20: 73.9704 | R20: 0 | S20: 1 | T20: 0 | U20: 0
A21: Fleet: getShipsLike(String) | B21: 3 | C21: 2 | D21: 1 | E21: 3 | F21: 1 | G21: 0 | H21: 8 | I21: 562.5922 | J21: 0.0227 | K21: 18 | L21: 15 | M21: 70.324 | N21: 1 | O21: 1 | P21: 21 | Q21: 58.09 | R21: 0 | S21: 4 | T21: 1 | U21: 1
A22: Fleet: getSunkShips() | B22: 3 | C22: 2 | D22: 1 | E22: 2 | F22: 1 | G22: 0 | H22: 6.6667 | I22: 299.8174 | J22: 0.0149 | K22: 13 | L22: 11 | M22: 44.9726 | N22: 1 | O22: 1 | P22: 19 | Q22: 60.4501 | R22: 0 | S22: 3 | T22: 1 | U22: 0
A23: Fleet: isInsideBoard(IShip) | B23: 4 | C23: 0 | D23: 0.25 | E23: 4 | F23: 0 | G23: 1 | H23: 14.4 | I23: 1589.2056 | J23: 0.0454 | K23: 27 | L23: 17 | M23: 110.3615 | N23: 0 | O23: 0 | P23: 12 | Q23: 61.9785 | R23: 0 | S23: 2 | T23: 0 | U23: 1
A24: Fleet: printAllShips() | B24: 1 | C24: 0 | D24: 0 | E24: 0 | F24: 0 | G24: 0 | H24: 1 | I24: 4.7549 | J24: 0.0009 | K24: 3 | L24: 3 | M24: 4.7549 | N24: 1 | O24: 0 | P24: 7 | Q24: 77.3494 | R24: 0 | S24: 1 | T24: 0 | U24: 0
A25: Fleet: printFloatingShips() | B25: 1 | C25: 0 | D25: 0 | E25: 0 | F25: 0 | G25: 0 | H25: 0 | I25: 0 | J25: 0 | K25: 4 | L25: 4 | M25: 8 | N25: 0 | O25: 0 | P25: 7 | Q25: 75.2416 | R25: 0 | S25: 0 | T25: 0 | U25: 0
A26: Fleet: printShips(List<IShip>) | B26: 2 | C26: 1 | D26: 1 | E26: 1 | F26: 0 | G26: 1 | H26: 3.75 | I26: 137.0295 | J26: 0.0089 | K26: 11 | L26: 10 | M26: 36.5412 | N26: 0 | O26: 1 | P26: 11 | Q26: 66.2926 | R26: 0 | S26: 3 | T26: 1 | U26: 1
... A74: IFleet: addShip(IShip) | B74: 1 | C74: 0 | D74: 0 | E74: 0 | F74: 0 | G74: 0 | H74: 0 | I74: 0 | J74: 0 | K74: 1 | L74: 1 | M74: 0 | N74: 0 | O74: 1 | P74: 0 | Q74: 0 | R74: 0 | S74: 0 | T74: 4 | U74: 1
A75: IFleet: getFloatingShips() | B75: 1 | C75: 0 | D75: 0 | E75: 0 | F75: 0 | G75: 0 | H75: 0 | K75: 0 | L75: 0 | N75: 0 | O75: 1 | P75: 0 | Q75: 0 | R75: 0 | S75: 0 | T75: 4 | U75: 0
A76: IFleet: getShips() | B76: 1 | C76: 0 | D76: 0 | E76: 0 | F76: 0 | G76: 0 | H76: 0 | K76: 0 | L76: 0 | N76: 0 | O76: 1 | P76: 0 | Q76: 0 | R76: 0 | S76: 0 | T76: 4 | U76: 0
A77: IFleet: getShipsLike(String) | B77: 1 | C77: 0 | D77: 0 | E77: 0 | F77: 0 | G77: 0 | H77: 0 | K77: 0 | L77: 0 | N77: 0 | O77: 1 | P77: 0 | Q77: 0 | R77: 0 | S77: 0 | T77: 4 | U77: 1
A78: IFleet: getSunkShips() | B78: 1 | C78: 0 | D78: 0 | E78: 0 | F78: 0 | G78: 0 | H78: 0 | K78: 0 | L78: 0 | N78: 0 | O78: 1 | P78: 0 | Q78: 0 | R78: 0 | S78: 0 | T78: 4 | U78: 0
A79: IFleet: printStatus() | B79: 1 | C79: 0 | D79: 0 | E79: 0 | F79: 0 | G79: 0 | H79: 0 | I79: 0 | J79: 0 | K79: 1 | L79: 1 | M79: 0 | N79: 0 | O79: 1 | P79: 0 | Q79: 0 | R79: 0 | S79: 0 | T79: 4 | U79: 0
A80: IFleet: shipAt(IPosition) | B80: 1 | C80: 0 | D80: 0 | E80: 0 | F80: 0 | G80: 0 | H80: 0 | K80: 0 | L80: 0 | N80: 0 | O80: 1 | P80: 0 | Q80: 0 | R80: 0 | S80: 0 | T80: 4 | U80: 1
A81: IGame: fireShots(List<IPosition>) | B81: 1 | C81: 0 | D81: 0 | E81: 0 | F81: 0 | G81: 0 | H81: 0 | I81: 0 | J81: 0 | K81: 1 | L81: 1 | M81: 0 | N81: 0 | O81: 0 | P81: 0 | Q81: 0 | R81: 0 | S81: 0 | T81: 0 | U81: 1
A82: IGame: fireSingleShot(IPosition, boolean) | B82: 1 | C82: 0 | D82: 0 | E82: 0 | F82: 0 | G82: 0 | H82: 0 | I82: 0 | J82: 0 | K82: 1 | L82: 1 | M82: 0 | N82: 0 | O82: 0 | P82: 0 | Q82: 0 | R82: 0 | S82: 0 | T82: 0 | U82: 2
A83: IGame: getAlienFleet() | B83: 1 | C83: 0 | D83: 0 | E83: 0 | F83: 0 | G83: 0 | H83: 0 | K83: 0 | L83: 0 | N83: 0 | O83: 0 | P83: 0 | Q83: 0 | R83: 0 | S83: 0 | T83: 0 | U83: 0
A84: IGame: getAlienMoves() | B84: 1 | C84: 0 | D84: 0 | E84: 0 | F84: 0 | G84: 0 | H84: 0 | K84: 0 | L84: 0 | N84: 0 | O84: 0 | P84: 0 | Q84: 0 | R84: 0 | S84: 0 | T84: 0 | U84: 0
A85: IGame: getHits() | B85: 1 | C85: 0 | D85: 0 | E85: 0 | F85: 0 | G85: 0 | H85: 0 | I85: 0 | J85: 0 | K85: 1 | L85: 1 | M85: 0 | N85: 0 | O85: 0 | P85: 0 | Q85: 0 | R85: 0 | S85: 0 | T85: 0 | U85: 0
A86: IGame: getInvalidShots() | B86: 1 | C86: 0 | D86: 0 | E86: 0 | F86: 0 | G86: 0 | H86: 0 | I86: 0 | J86: 0 | K86: 1 | L86: 1 | M86: 0 | N86: 0 | O86: 0 | P86: 0 | Q86: 0 | R86: 0 | S86: 0 | T86: 0 | U86: 0
A87: IGame: getMyFleet() | B87: 1 | C87: 0 | D87: 0 | E87: 0 | F87: 0 | G87: 0 | H87: 0 | K87: 0 | L87: 0 | N87: 0 | O87: 0 | P87: 0 | Q87: 0 | R87: 0 | S87: 0 | T87: 0 | U87: 0
...

Sheet IGE-93263-Metrics
A1: /Metrics/Metric/@description | B1: /Metrics/Metric/@name | C1: /Metrics/Metric/@value | D1: /Packages/Package/@name | E1: /Packages/Package/Class/@name | F1: /Packages/Package/Class/#id | G1: /Packages/Package/Class/Class/@name | H1: /Packages/Package/Class/Class/Method/@name | I1: /Packages/Package/Class/Class/Method/#id | J1: /Packages/Package/Class/Class/Method/Metrics/Metric/@description | K1: /Packages/Package/Class/Class/Method/Metrics/Metric/@name | L1: /Packages/Package/Class/Class/Method/Metrics/Metric/@value | M1: /Packages/Package/Class/Class/Metrics/Metric/@description | N1: /Packages/Package/Class/Class/Metrics/Metric/@name | O1: /Packages/Package/Class/Class/Metrics/Metric/@value | P1: /Packages/Package/Class/Method/@name | Q1: /Packages/Package/Class/Method/#id | R1: /Packages/Package/Class/Method/Metrics/Metric/@description | S1: /Packages/Package/Class/Method/Metrics/Metric/@name | T1: /Packages/Package/Class/Method/Metrics/Metric/@value | U1: /Packages/Package/Class/Metrics/Metric/@description | V1: /Packages/Package/Class/Metrics/Metric/@name | W1: /Packages/Package/Class/Metrics/Metric/@value | X1: /Packages/Package/Metrics/Metric/@description | Y1: /Packages/Package/Metrics/Metric/@name | Z1: /Packages/Package/Metrics/Metric/@value
A2: Attribute Hiding Factor | B2: AHF | C2: 0
A3: Attribute Inheritance Factor | B3: AIF | C3: 0.0897
A4: Coupling Factor | B4: CF | C4: 0.7333
A5: Effectiveness | B5: Effectiveness | C5: 1.5585
A6: Extendibility | B6: Extendibility | C6: 2.2156
A7: Flexibility | B7: Flexibility | C7: 3.6461
A8: Functionality | B8: Functionality | C8: 2.0227
A9: Halstead Difficulty | B9: PRHD | C9: 1025.5611
A10: Halstead Effort | B10: PRCHEF | C10: 4434629.9
A11: Halstead Errors | B11: PRCHER | C11: 16.0967
A12: Halstead Length | B12: PRCHL | C12: 4574
A13: Halstead Vocabulary | B13: PRCHVC | C13: 1231
... A30: Understandability | B30: Understandability | C30: -2.3693
D31: battleship | E31: Barge | F31: 1 | P31: Barge(Compass, IPosition) | Q31: 1 | R31: Cognitive Complexity | S31: CCM | T31: 0
D32: battleship | E32: Barge | F32: 1 | P32: Barge(Compass, IPosition) | Q32: 1 | R32: Condition Nesting Depth | S32: CND | T32: 0
D33: battleship | E33: Barge | F33: 1 | P33: Barge(Compass, IPosition) | Q33: 1 | R33: Coupling Dispersion | S33: CDISP | T33: 0.6
D34: battleship | E34: Barge | F34: 1 | P34: Barge(Compass, IPosition) | Q34: 1 | R34: Coupling Intensity | S34: CINT | T34: 5
D35: battleship | E35: Barge | F35: 1 | P35: Barge(Compass, IPosition) | Q35: 1 | R35: Foreign Data Providers | S35: FDP | T35: 0
D36: battleship | E36: Barge | F36: 1 | P36: Barge(Compass, IPosition) | Q36: 1 | R36: Halstead Difficulty | S36: HD | T36: 6
D37: battleship | E37: Barge | F37: 1 | P37: Barge(Compass, IPosition) | Q37: 1 | R37: Halstead Effort | S37: HEF | T37: 301.1369
D38: battleship | E38: Barge | F38: 1 | P38: Barge(Compass, IPosition) | Q38: 1 | R38: Halstead Errors | S38: HER | T38: 0.015
D39: battleship | E39: Barge | F39: 1 | P39: Barge(Compass, IPosition) | Q39: 1 | R39: Halstead Length | S39: HL | T39: 14
D40: battleship | E40: Barge | F40: 1 | P40: Barge(Compass, IPosition) | Q40: 1 | R40: Halstead Vocabulary | S40: HVC | T40: 12
D41: battleship | E41: Barge | F41: 1 | P41: Barge(Compass, IPosition) | Q41: 1 | R41: Halstead Volume | S41: HVL | T41: 50.1895
D42: battleship | E42: Barge | F42: 1 | P42: Barge(Compass, IPosition) | Q42: 1 | R42: Lines Of Code | S42: LOC | T42: 11
... D50: battleship | E50: Barge | F50: 1 | P50: Barge(Compass, IPosition) | Q50: 1 | R50: Number Of Parameters | S50: NOPM | T50: 2
D51: battleship | E51: Barge | F51: 1 | U51: Access To Foreign Data | V51: ATFD | W51: 1
D52: battleship | E52: Barge | F52: 1 | U52: Cognitive Complexity | V52: CCC | W52: 0
D53: battleship | E53: Barge | F53: 1 | U53: Coupling Between Objects | V53: CBO | W53: 5
D54: battleship | E54: Barge | F54: 1 | U54: Data Abstraction Coupling | V54: DAC | W54: 0
D55: battleship | E55: Barge | F55: 1 | U55: Depth Of Inheritance Tree | V55: DIT | W55: 2
D56: battleship | E56: Barge | F56: 1 | U56: Halstead Difficulty | V56: CHD | W56: 7.5
D57: battleship | E57: Barge | F57: 1 | U57: Halstead Effort | V57: CHEF | W57: 485.4378
D58: battleship | E58: Barge | F58: 1 | U58: Halstead Errors | V58: CHER | W58: 0.0206
D59: battleship | E59: Barge | F59: 1 | U59: Halstead Length | V59: CHL | W59: 17
D60: battleship | E60: Barge | F60: 1 | U60: Halstead Vocabulary | V60: CHVC | W60: 14
D61: battleship | E61: Barge | F61: 1 | U61: Halstead Volume | V61: CHVL | W61: 64.725
D62: battleship | E62: Barge | F62: 1 | U62: Lack Of Cohesion Of Methods | V62: LCOM | W62: 0
... D79: battleship | E79: Barge | F79: 1 | U79: Weighted Methods Per Class | V79: WMC | W79: 1
...

Sheet System
A1: /Metrics/Metric/@description | B1: /Metrics/Metric/@name | C1: /Metrics/Metric/@value
A2: Attribute Hiding Factor | B2: AHF | C2: 0
A3: Attribute Inheritance Factor | B3: AIF | C3: 0.0897
A4: Coupling Factor | B4: CF | C4: 0.7333
A5: Effectiveness | B5: Effectiveness | C5: 1.5585
A6: Extendibility | B6: Extendibility | C6: 2.2156
A7: Flexibility | B7: Flexibility | C7: 3.6461
A8: Functionality | B8: Functionality | C8: 2.0227
A9: Halstead Difficulty | B9: PRHD | C9: 1025.5611
A10: Halstead Effort | B10: PRCHEF | C10: 4434629.9
A11: Halstead Errors | B11: PRCHER | C11: 16.0967
A12: Halstead Length | B12: PRCHL | C12: 4574
A13: Halstead Vocabulary | B13: PRCHVC | C13: 1231
... A30: Understandability | B30: Understandability | C30: -2.3693

Sheet Package
A1: /Packages/Package/@name | B1: /Packages/Package/Class/@name | C1: /Packages/Package/Class/#id | D1: /Packages/Package/Class/Class/@name
A31: battleship | B31: Barge | C31: 1
A32: battleship | B32: Barge | C32: 1
A33: battleship | B33: Barge | C33: 1
A34: battleship | B34: Barge | C34: 1
A35: battleship | B35: Barge | C35: 1
A36: battleship | B36: Barge | C36: 1
A37: battleship | B37: Barge | C37: 1
A38: battleship | B38: Barge | C38: 1
A39: battleship | B39: Barge | C39: 1
A40: battleship | B40: Barge | C40: 1
A41: battleship | B41: Barge | C41: 1
A42: battleship | B42: Barge | C42: 1
... A1929: battleship | B1929: IFleet | C1929: 11
A1930: battleship | B1930: IGame | C1930: 12 | D1930: ShotResult
A1931: battleship | B1931: IGame | C1931: 12 | D1931: ShotResult
A1932: battleship | B1932: IGame | C1932: 12 | D1932: ShotResult
A1933: battleship | B1933: IGame | C1933: 12 | D1933: ShotResult
A1934: battleship | B1934: IGame | C1934: 12 | D1934: ShotResult
A1935: battleship | B1935: IGame | C1935: 12 | D1935: ShotResult
A1936: battleship | B1936: IGame | C1936: 12 | D1936: ShotResult
A1937: battleship | B1937: IGame | C1937: 12 | D1937: ShotResult
A1938: battleship | B1938: IGame | C1938: 12 | D1938: ShotResult
A1939: battleship | B1939: IGame | C1939: 12 | D1939: ShotResult
A1940: battleship | B1940: IGame | C1940: 12 | D1940: ShotResult
A1941: battleship | B1941: IGame | C1941: 12 | D1941: ShotResult
... A2058: battleship | B2058: IGame | C2058: 12 | D2058: ShotResult
A2059: battleship | B2059: IGame | C2059: 12
A2060: battleship | B2060: IGame | C2060: 12
A2061: battleship | B2061: IGame | C2061: 12
A2062: battleship | B2062: IGame | C2062: 12
A2063: battleship | B2063: IGame | C2063: 12
A2064: battleship | B2064: IGame | C2064: 12
A2065: battleship | B2065: IGame | C2065: 12
A2066: battleship | B2066: IGame | C2066: 12
A2067: battleship | B2067: IGame | C2067: 12
A2068: battleship | B2068: IGame | C2068: 12
A2069: battleship | B2069: IGame | C2069: 12
A2070: battleship | B2070: IGame | C2070: 12
... A3372: battleship | B3372: Move | C3372: 17
...

Sheet Class
A1: /Packages/Package/Class/Class/Method/@name | B1: /Packages/Package/Class/Class/Method/#id | C1: /Packages/Package/Class/Class/Method/Metrics/Metric/@description | D1: /Packages/Package/Class/Class/Method/Metrics/Metric/@name
A1930: ShotResult(boolean, boolean, IShip, boolean) | B1930: 1 | C1930: Cognitive Complexity | D1930: CCM
A1931: ShotResult(boolean, boolean, IShip, boolean) | B1931: 1 | C1931: Condition Nesting Depth | D1931: CND
A1932: ShotResult(boolean, boolean, IShip, boolean) | B1932: 1 | C1932: Coupling Dispersion | D1932: CDISP
A1933: ShotResult(boolean, boolean, IShip, boolean) | B1933: 1 | C1933: Coupling Intensity | D1933: CINT
A1934: ShotResult(boolean, boolean, IShip, boolean) | B1934: 1 | C1934: Foreign Data Providers | D1934: FDP
A1935: ShotResult(boolean, boolean, IShip, boolean) | B1935: 1 | C1935: Halstead Difficulty | D1935: HD
A1936: ShotResult(boolean, boolean, IShip, boolean) | B1936: 1 | C1936: Halstead Effort | D1936: HEF
A1937: ShotResult(boolean, boolean, IShip, boolean) | B1937: 1 | C1937: Halstead Errors | D1937: HER
A1938: ShotResult(boolean, boolean, IShip, boolean) | B1938: 1 | C1938: Halstead Length | D1938: HL
A1939: ShotResult(boolean, boolean, IShip, boolean) | B1939: 1 | C1939: Halstead Vocabulary | D1939: HVC
A1940: ShotResult(boolean, boolean, IShip, boolean) | B1940: 1 | C1940: Halstead Volume | D1940: HVL
A1941: ShotResult(boolean, boolean, IShip, boolean) | B1941: 1 | C1941: Lines Of Code | D1941: LOC
... A3392: PdfState(PDPage, PDPageContentStream, float) | B3392: 6 | C3392: Number Of Parameters | D3392: NOPM

Sheet Method
A1: /Packages/Package/Class/Class/Method/Metrics/Metric/@value | B1: /Packages/Package/Class/Class/Metrics/Metric/@description | C1: /Packages/Package/Class/Class/Metrics/Metric/@name | D1: /Packages/Package/Class/Class/Metrics/Metric/@value | E1: /Packages/Package/Class/Method/@name | F1: /Packages/Package/Class/Method/#id | G1: /Packages/Package/Class/Method/Metrics/Metric/@description | H1: /Packages/Package/Class/Method/Metrics/Metric/@name | I1: /Packages/Package/Class/Method/Metrics/Metric/@value | J1: /Packages/Package/Class/Metrics/Metric/@description | K1: /Packages/Package/Class/Metrics/Metric/@name | L1: /Packages/Package/Class/Metrics/Metric/@value | M1: /Packages/Package/Metrics/Metric/@description | N1: /Packages/Package/Metrics/Metric/@name | O1: /Packages/Package/Metrics/Metric/@value
E2: processEnemyFire(boolean) | F2: 135 | G2: Lines Of Code | H2: LOC | I2: 132
E3: menu() | F3: 182 | G3: Lines Of Code | H3: LOC | I3: 122
E4: printBoard(IFleet, List<IMove>, boolean, boolean) | F4: 54 | G4: McCabe Cyclomatic Complexity | H4: 0 | I4: 20
E5: printMoveSection(PDDocument, PdfState, String, List<IMove>) | F5: 139 | G5: Lines Of Code | H5: LOC | I5: 71
E6: printBoard(IFleet, List<IMove>, boolean, boolean) | F6: 54 | G6: Lines Of Code | H6: LOC | I6: 70
E7: readEnemyFire(Scanner) | F7: 60 | G7: Lines Of Code | H7: LOC | I7: 52
E8: readAlienFire(Scanner) | F8: 59 | G8: Lines Of Code | H8: LOC | I8: 50
E9: randomEnemyFire() | F9: 57 | G9: Lines Of Code | H9: LOC | I9: 46
E10: displayScoreboard(int) | F10: 157 | G10: Lines Of Code | H10: LOC | I10: 44
E11: createBoardPanel(char[][], List<IPosition>) | F11: 3 | G11: Lines Of Code | H11: LOC | I11: 43
E12: buildMap(IFleet, List<IMove>, boolean, boolean) | F12: 36 | G12: Lines Of Code | H12: LOC | I12: 43
E13: randomPlayerFire() | F13: 58 | G13: Lines Of Code | H13: LOC | I13: 42
E14: processEnemyFire(boolean) | F14: 135 | G14: McCabe Cyclomatic Complexity | H14: CC | I14: 38
E15: jsonShots(List<IPosition>) | F15: 50 | G15: Lines Of Code | H15: LOC | I15: 38
E16: buildShip(String, Compass, Position) | F16: 162 | G16: Lines Of Code | H16: LOC | I16: 36
... E1314: toString() | F1314: 11 | G1314: Halstead Effort | H1314: HEF | I1314: 17.4145
E1315: valueOf(String) | F1315: 12 | G1315: Halstead Effort | H1315: HEF | I1315: NaN
E1316: values() | F1316: 13 | G1316: Halstead Effort | H1316: HEF | I1316: NaN
E1317: Fleet() | F1317: 14 | G1317: Halstead Effort | H1317: HEF | I1317: 4.7549
E1318: addShip(IShip) | F1318: 15 | G1318: Halstead Effort | H1318: HEF | I1318: 1092.3242
E1319: colisionRisk(IShip) | F1319: 16 | G1319: Halstead Effort | H1319: HEF | I1319: 1103.6352
E1320: createRandom() | F1320: 17 | G1320: Halstead Effort | H1320: HEF | I1320: 2597.3573
E1321: getFloatingShips() | F1321: 18 | G1321: Halstead Effort | H1321: HEF | I1321: 232.535
E1322: getShips() | F1322: 19 | G1322: Halstead Effort | H1322: HEF | I1322: 4.7549
E1323: getShipsLike(String) | F1323: 20 | G1323: Halstead Effort | H1323: HEF | I1323: 562.5922
E1324: getSunkShips() | F1324: 21 | G1324: Halstead Effort | H1324: HEF | I1324: 299.8174
E1325: isInsideBoard(IShip) | F1325: 22 | G1325: Halstead Effort | H1325: HEF | I1325: 1589.2056
E1326: printAllShips() | F1326: 23 | G1326: Halstead Effort | H1326: HEF | I1326: 4.7549
E1327: printFloatingShips() | F1327: 24 | G1327: Halstead Effort | H1327: HEF | I1327: 0
E1328: printShips(List<IShip>) | F1328: 25 | G1328: Halstead Effort | H1328: HEF | I1328: 137.0295
... E1376: addShip(IShip) | F1376: 73 | G1376: Halstead Effort | H1376: HEF | I1376: 0
E1377: getFloatingShips() | F1377: 74 | G1377: Halstead Effort | H1377: HEF | I1377: NaN
E1378: getShips() | F1378: 75 | G1378: Halstead Effort | H1378: HEF | I1378: NaN
E1379: getShipsLike(String) | F1379: 76 | G1379: Halstead Effort | H1379: HEF | I1379: NaN
E1380: getSunkShips() | F1380: 77 | G1380: Halstead Effort | H1380: HEF | I1380: NaN
E1381: printStatus() | F1381: 78 | G1381: Halstead Effort | H1381: HEF | I1381: 0
E1382: shipAt(IPosition) | F1382: 79 | G1382: Halstead Effort | H1382: HEF | I1382: NaN
E1383: fireShots(List<IPosition>) | F1383: 80 | G1383: Halstead Effort | H1383: HEF | I1383: 0
E1384: fireSingleShot(IPosition, boolean) | F1384: 81 | G1384: Halstead Effort | H1384: HEF | I1384: 0
...

Sheet Graficos

Sheet Todas Métricas Norm
A1: Dados (referência MethodData) | W1: Normalização [0, 1]
A2: MIN | B2: =MIN(B5:B190) -> 0 | C2: =MIN(C5:C190) -> 0 | D2: =MIN(D5:D190) -> 0 | E2: =MIN(E5:E190) -> 0 | F2: =MIN(F5:F190) -> 0 | G2: =MIN(G5:G190) -> 0 | H2: =MIN(H5:H190) -> 0 | I2: =MIN(I5:I190) -> 0 | ... U2: =MIN(U5:U190) -> 0
A3: MAX | B3: =MAX(B5:B190) -> 38 | C3: =MAX(C5:C190) -> 40 | D3: =MAX(D5:D190) -> 1 | E3: =MAX(E5:E190) -> 29 | F3: =MAX(F5:F190) -> 4 | G3: =MAX(G5:G190) -> 5 | H3: =MAX(H5:H190) -> 100.1 | I3: =MAX(I5:I190) -> 190025.49 | ... U3: =MAX(U5:U190) -> 4
A4: Classe.Método | B4: CC | C4: CCM | D4: CDISP | E4: CINT | F4: CND | G4: FDP | H4: HD | I4: HEF | J4: HER | K4: HL | L4: HVC | M4: HVL | N4: LAA | O4: LND | P4: LOC | Q4: MMI | R4: MND | S4: NOAV | T4: NOL | U4: NOPM | W4: CC norm | X4: CCM norm | Y4: CDISP norm | Z4: CINT norm | AA4: CND norm | AB4: FDP norm | AC4: HD norm | AD4: HEF norm | AE4: HER norm | AF4: HL norm | AG4: HVC norm | AH4: HVL norm | AI4: LAA norm | AJ4: LND norm | AK4: LOC norm | AL4: MMI norm | AM4: MND norm | AN4: NOAV norm | AO4: NOL norm | AP4: NOPM norm | AQ4: SOMA norm
A5: =MethodData!A2 -> Barge: Barge(Compass, IPosition) | B5: =MethodData!B2 -> 1 | C5: =MethodData!C2 -> 0 | D5: =MethodData!D2 -> 0.6 | E5: =MethodData!E2 -> 5 | F5: =MethodData!F2 -> 0 | G5: =MethodData!G2 -> 0 | H5: =MethodData!H2 -> 6 | ... U5: =MethodData!U2 -> 2 | W5: =IF(B$3-B$2=0,0,(B5-B$2)/(B$3-B$2)) -> 0.026315789 | X5: =IF(C$3-C$2=0,0,(C5-C$2)/(C$3-C$2)) -> 0 | Y5: =IF(D$3-D$2=0,0,(D5-D$2)/(D$3-D$2)) -> 0.6 | Z5: =IF(E$3-E$2=0,0,(E5-E$2)/(E$3-E$2)) -> 0.17241379 | AA5: =IF(F$3-F$2=0,0,(F5-F$2)/(F$3-F$2)) -> 0 | AB5: =IF(G$3-G$2=0,0,(G5-G$2)/(G$3-G$2)) -> 0 | AC5: =IF(H$3-H$2=0,0,(H5-H$2)/(H$3-H$2)) -> 0.05994006 | AD5: =IF(I$3-I$2=0,0,(I5-I$2)/(I$3-I$2)) -> 0.0015847185 | ... AP5: =IF(U$3-U$2=0,0,(U5-U$2)/(U$3-U$2)) -> 0.5 | AQ5: =SUM(W5:AP5) -> 2.551825
A6: =MethodData!A3 -> BoardWindow: close() | B6: =MethodData!B3 -> 2 | C6: =MethodData!C3 -> 1 | D6: =MethodData!D3 -> 1 | E6: =MethodData!E3 -> 1 | F6: =MethodData!F3 -> 1 | G6: =MethodData!G3 -> 0 | H6: =MethodData!H3 -> 7.5 | ... U6: =MethodData!U3 -> 0 | W6: =IF(B$3-B$2=0,0,(B6-B$2)/(B$3-B$2)) -> 0.052631579 | X6: =IF(C$3-C$2=0,0,(C6-C$2)/(C$3-C$2)) -> 0.025 | Y6: =IF(D$3-D$2=0,0,(D6-D$2)/(D$3-D$2)) -> 1 | Z6: =IF(E$3-E$2=0,0,(E6-E$2)/(E$3-E$2)) -> 0.034482759 | AA6: =IF(F$3-F$2=0,0,(F6-F$2)/(F$3-F$2)) -> 0.25 | AB6: =IF(G$3-G$2=0,0,(G6-G$2)/(G$3-G$2)) -> 0 | AC6: =IF(H$3-H$2=0,0,(H6-H$2)/(H$3-H$2)) -> 0.074925075 | AD6: =IF(I$3-I$2=0,0,(I6-I$2)/(I$3-I$2)) -> 0.0013024569 | ... AP6: =IF(U$3-U$2=0,0,(U6-U$2)/(U$3-U$2)) -> 0 | AQ6: =SUM(W6:AP6) -> 3.7409393
A7: =MethodData!A4 -> BoardWindow: createBoardPanel(char[][], List<IPosition>) | B7: =MethodData!B4 -> 10 | C7: =MethodData!C4 -> 10 | D7: =MethodData!D4 -> 0.5 | E7: =MethodData!E4 -> 10 | F7: =MethodData!F4 -> 2 | G7: =MethodData!G4 -> 4 | H7: =MethodData!H4 -> 27.5 | ... U7: =MethodData!U4 -> 2 | W7: =IF(B$3-B$2=0,0,(B7-B$2)/(B$3-B$2)) -> 0.26315789 | X7: =IF(C$3-C$2=0,0,(C7-C$2)/(C$3-C$2)) -> 0.25 | Y7: =IF(D$3-D$2=0,0,(D7-D$2)/(D$3-D$2)) -> 0.5 | Z7: =IF(E$3-E$2=0,0,(E7-E$2)/(E$3-E$2)) -> 0.34482759 | AA7: =IF(F$3-F$2=0,0,(F7-F$2)/(F$3-F$2)) -> 0.5 | AB7: =IF(G$3-G$2=0,0,(G7-G$2)/(G$3-G$2)) -> 0.8 | AC7: =IF(H$3-H$2=0,0,(H7-H$2)/(H$3-H$2)) -> 0.27472527 | AD7: =IF(I$3-I$2=0,0,(I7-I$2)/(I$3-I$2)) -> 0.099562958 | ... AP7: =IF(U$3-U$2=0,0,(U7-U$2)/(U$3-U$2)) -> 0.5 | AQ7: =SUM(W7:AP7) -> 8.5610984
A8: =MethodData!A5 -> BoardWindow: show(char[][], char[][], List<IPosition>, List<IPosition>) | B8: =MethodData!B5 -> 2 | C8: =MethodData!C5 -> 1 | D8: =MethodData!D5 -> 0.4545 | E8: =MethodData!E5 -> 10 | F8: =MethodData!F5 -> 1 | G8: =MethodData!G5 -> 4 | H8: =MethodData!H5 -> 16.7143 | ... U8: =MethodData!U5 -> 4 | W8: =IF(B$3-B$2=0,0,(B8-B$2)/(B$3-B$2)) -> 0.052631579 | X8: =IF(C$3-C$2=0,0,(C8-C$2)/(C$3-C$2)) -> 0.025 | Y8: =IF(D$3-D$2=0,0,(D8-D$2)/(D$3-D$2)) -> 0.4545 | Z8: =IF(E$3-E$2=0,0,(E8-E$2)/(E$3-E$2)) -> 0.34482759 | AA8: =IF(F$3-F$2=0,0,(F8-F$2)/(F$3-F$2)) -> 0.25 | AB8: =IF(G$3-G$2=0,0,(G8-G$2)/(G$3-G$2)) -> 0.8 | AC8: =IF(H$3-H$2=0,0,(H8-H$2)/(H$3-H$2)) -> 0.16697602 | AD8: =IF(I$3-I$2=0,0,(I8-I$2)/(I$3-I$2)) -> 0.04275411 | ... AP8: =IF(U$3-U$2=0,0,(U8-U$2)/(U$3-U$2)) -> 1 | AQ8: =SUM(W8:AP8) -> 6.0697069
A9: =MethodData!A6 -> Caravel: Caravel(Compass, IPosition) | B9: =MethodData!B6 -> 9 | C9: =MethodData!C6 -> 5 | D9: =MethodData!D6 -> 0.5 | E9: =MethodData!E6 -> 6 | F9: =MethodData!F6 -> 0 | G9: =MethodData!G6 -> 1 | H9: =MethodData!H6 -> 27 | ... U9: =MethodData!U6 -> 2 | W9: =IF(B$3-B$2=0,0,(B9-B$2)/(B$3-B$2)) -> 0.23684211 | X9: =IF(C$3-C$2=0,0,(C9-C$2)/(C$3-C$2)) -> 0.125 | Y9: =IF(D$3-D$2=0,0,(D9-D$2)/(D$3-D$2)) -> 0.5 | Z9: =IF(E$3-E$2=0,0,(E9-E$2)/(E$3-E$2)) -> 0.20689655 | AA9: =IF(F$3-F$2=0,0,(F9-F$2)/(F$3-F$2)) -> 0 | AB9: =IF(G$3-G$2=0,0,(G9-G$2)/(G$3-G$2)) -> 0.2 | AC9: =IF(H$3-H$2=0,0,(H9-H$2)/(H$3-H$2)) -> 0.26973027 | AD9: =IF(I$3-I$2=0,0,(I9-I$2)/(I$3-I$2)) -> 0.064193443 | ... AP9: =IF(U$3-U$2=0,0,(U9-U$2)/(U$3-U$2)) -> 0.5 | AQ9: =SUM(W9:AP9) -> 5.042861
A10: =MethodData!A7 -> Carrack: Carrack(Compass, IPosition) | B10: =MethodData!B7 -> 9 | C10: =MethodData!C7 -> 5 | D10: =MethodData!D7 -> 0.5 | E10: =MethodData!E7 -> 6 | F10: =MethodData!F7 -> 0 | G10: =MethodData!G7 -> 1 | H10: =MethodData!H7 -> 27 | ... U10: =MethodData!U7 -> 2 | W10: =IF(B$3-B$2=0,0,(B10-B$2)/(B$3-B$2)) -> 0.23684211 | X10: =IF(C$3-C$2=0,0,(C10-C$2)/(C$3-C$2)) -> 0.125 | Y10: =IF(D$3-D$2=0,0,(D10-D$2)/(D$3-D$2)) -> 0.5 | Z10: =IF(E$3-E$2=0,0,(E10-E$2)/(E$3-E$2)) -> 0.20689655 | AA10: =IF(F$3-F$2=0,0,(F10-F$2)/(F$3-F$2)) -> 0 | AB10: =IF(G$3-G$2=0,0,(G10-G$2)/(G$3-G$2)) -> 0.2 | AC10: =IF(H$3-H$2=0,0,(H10-H$2)/(H$3-H$2)) -> 0.26973027 | AD10: =IF(I$3-I$2=0,0,(I10-I$2)/(I$3-I$2)) -> 0.064193443 | ... AP10: =IF(U$3-U$2=0,0,(U10-U$2)/(U$3-U$2)) -> 0.5 | AQ10: =SUM(W10:AP10) -> 5.042861
A11: =MethodData!A8 -> Compass: Compass(char) | B11: =MethodData!B8 -> 1 | C11: =MethodData!C8 -> 0 | D11: =MethodData!D8 -> 0 | E11: =MethodData!E8 -> 0 | F11: =MethodData!F8 -> 0 | G11: =MethodData!G8 -> 0 | H11: =MethodData!H8 -> 1 | ... U11: =MethodData!U8 -> 1 | W11: =IF(B$3-B$2=0,0,(B11-B$2)/(B$3-B$2)) -> 0.026315789 | X11: =IF(C$3-C$2=0,0,(C11-C$2)/(C$3-C$2)) -> 0 | Y11: =IF(D$3-D$2=0,0,(D11-D$2)/(D$3-D$2)) -> 0 | Z11: =IF(E$3-E$2=0,0,(E11-E$2)/(E$3-E$2)) -> 0 | AA11: =IF(F$3-F$2=0,0,(F11-F$2)/(F$3-F$2)) -> 0 | AB11: =IF(G$3-G$2=0,0,(G11-G$2)/(G$3-G$2)) -> 0 | AC11: =IF(H$3-H$2=0,0,(H11-H$2)/(H$3-H$2)) -> 0.00999001 | AD11: =IF(I$3-I$2=0,0,(I11-I$2)/(I$3-I$2)) -> 4.2099615e-05 | ... AP11: =IF(U$3-U$2=0,0,(U11-U$2)/(U$3-U$2)) -> 0.25 | AQ11: =SUM(W11:AP11) -> 2.4024622
A12: =MethodData!A9 -> Compass: charToCompass(char) | B12: =MethodData!B9 -> 6 | C12: =MethodData!C9 -> 1 | D12: =MethodData!D9 -> 0 | E12: =MethodData!E9 -> 0 | F12: =MethodData!F9 -> 0 | G12: =MethodData!G9 -> 0 | H12: =MethodData!H9 -> 5.0909 | ... U12: =MethodData!U9 -> 1 | W12: =IF(B$3-B$2=0,0,(B12-B$2)/(B$3-B$2)) -> 0.15789474 | X12: =IF(C$3-C$2=0,0,(C12-C$2)/(C$3-C$2)) -> 0.025 | Y12: =IF(D$3-D$2=0,0,(D12-D$2)/(D$3-D$2)) -> 0 | Z12: =IF(E$3-E$2=0,0,(E12-E$2)/(E$3-E$2)) -> 0 | AA12: =IF(F$3-F$2=0,0,(F12-F$2)/(F$3-F$2)) -> 0 | AB12: =IF(G$3-G$2=0,0,(G12-G$2)/(G$3-G$2)) -> 0 | AC12: =IF(H$3-H$2=0,0,(H12-H$2)/(H$3-H$2)) -> 0.050858142 | AD12: =IF(I$3-I$2=0,0,(I12-I$2)/(I$3-I$2)) -> 0.003239737 | ... AP12: =IF(U$3-U$2=0,0,(U12-U$2)/(U$3-U$2)) -> 0.25 | AQ12: =SUM(W12:AP12) -> 3.1192579
A13: =MethodData!A10 -> Compass: getDirection() | B13: =MethodData!B10 -> 1 | C13: =MethodData!C10 -> 0 | D13: =MethodData!D10 -> 0 | E13: =MethodData!E10 -> 0 | F13: =MethodData!F10 -> 0 | G13: =MethodData!G10 -> 0 | H13: =MethodData!H10 -> 1.5 | ... U13: =MethodData!U10 -> 0 | W13: =IF(B$3-B$2=0,0,(B13-B$2)/(B$3-B$2)) -> 0.026315789 | X13: =IF(C$3-C$2=0,0,(C13-C$2)/(C$3-C$2)) -> 0 | Y13: =IF(D$3-D$2=0,0,(D13-D$2)/(D$3-D$2)) -> 0 | Z13: =IF(E$3-E$2=0,0,(E13-E$2)/(E$3-E$2)) -> 0 | AA13: =IF(F$3-F$2=0,0,(F13-F$2)/(F$3-F$2)) -> 0 | AB13: =IF(G$3-G$2=0,0,(G13-G$2)/(G$3-G$2)) -> 0 | AC13: =IF(H$3-H$2=0,0,(H13-H$2)/(H$3-H$2)) -> 0.014985015 | AD13: =IF(I$3-I$2=0,0,(I13-I$2)/(I$3-I$2)) -> 6.3149423e-05 | ... AP13: =IF(U$3-U$2=0,0,(U13-U$2)/(U$3-U$2)) -> 0 | AQ13: =SUM(W13:AP13) -> 2.1255833
A14: =MethodData!A11 -> Compass: randomBearing() | B14: =MethodData!B11 -> 1 | C14: =MethodData!C11 -> 0 | D14: =MethodData!D11 -> 0.5 | E14: =MethodData!E11 -> 1 | F14: =MethodData!F11 -> 0 | G14: =MethodData!G11 -> 1 | H14: =MethodData!H11 -> 4.6667 | ... U14: =MethodData!U11 -> 0 | W14: =IF(B$3-B$2=0,0,(B14-B$2)/(B$3-B$2)) -> 0.026315789 | X14: =IF(C$3-C$2=0,0,(C14-C$2)/(C$3-C$2)) -> 0 | Y14: =IF(D$3-D$2=0,0,(D14-D$2)/(D$3-D$2)) -> 0.5 | Z14: =IF(E$3-E$2=0,0,(E14-E$2)/(E$3-E$2)) -> 0.034482759 | AA14: =IF(F$3-F$2=0,0,(F14-F$2)/(F$3-F$2)) -> 0 | AB14: =IF(G$3-G$2=0,0,(G14-G$2)/(G$3-G$2)) -> 0.2 | AC14: =IF(H$3-H$2=0,0,(H14-H$2)/(H$3-H$2)) -> 0.04662038 | AD14: =IF(I$3-I$2=0,0,(I14-I$2)/(I$3-I$2)) -> 0.00097896341 | ... AP14: =IF(U$3-U$2=0,0,(U14-U$2)/(U$3-U$2)) -> 0 | AQ14: =SUM(W14:AP14) -> 2.0082117
A15: =MethodData!A12 -> Compass: toString() | B15: =MethodData!B12 -> 1 | C15: =MethodData!C12 -> 0 | D15: =MethodData!D12 -> 0 | E15: =MethodData!E12 -> 0 | F15: =MethodData!F12 -> 0 | G15: =MethodData!G12 -> 0 | H15: =MethodData!H12 -> 1.5 | ... U15: =MethodData!U12 -> 0 | W15: =IF(B$3-B$2=0,0,(B15-B$2)/(B$3-B$2)) -> 0.026315789 | X15: =IF(C$3-C$2=0,0,(C15-C$2)/(C$3-C$2)) -> 0 | Y15: =IF(D$3-D$2=0,0,(D15-D$2)/(D$3-D$2)) -> 0 | Z15: =IF(E$3-E$2=0,0,(E15-E$2)/(E$3-E$2)) -> 0 | AA15: =IF(F$3-F$2=0,0,(F15-F$2)/(F$3-F$2)) -> 0 | AB15: =IF(G$3-G$2=0,0,(G15-G$2)/(G$3-G$2)) -> 0 | AC15: =IF(H$3-H$2=0,0,(H15-H$2)/(H$3-H$2)) -> 0.014985015 | AD15: =IF(I$3-I$2=0,0,(I15-I$2)/(I$3-I$2)) -> 9.1642969e-05 | ... AP15: =IF(U$3-U$2=0,0,(U15-U$2)/(U$3-U$2)) -> 0 | AQ15: =SUM(W15:AP15) -> 2.1274925
A16: =MethodData!A13 -> Compass: valueOf(String) | B16: =MethodData!B13 -> 1 | C16: =MethodData!C13 -> 0 | D16: =MethodData!D13 -> 0 | E16: =MethodData!E13 -> 0 | F16: =MethodData!F13 -> 0 | G16: =MethodData!G13 -> 0 | H16: =MethodData!H13 -> 0 | ... U16: =MethodData!U13 -> 1 | W16: =IF(B$3-B$2=0,0,(B16-B$2)/(B$3-B$2)) -> 0.026315789 | X16: =IF(C$3-C$2=0,0,(C16-C$2)/(C$3-C$2)) -> 0 | Y16: =IF(D$3-D$2=0,0,(D16-D$2)/(D$3-D$2)) -> 0 | Z16: =IF(E$3-E$2=0,0,(E16-E$2)/(E$3-E$2)) -> 0 | AA16: =IF(F$3-F$2=0,0,(F16-F$2)/(F$3-F$2)) -> 0 | AB16: =IF(G$3-G$2=0,0,(G16-G$2)/(G$3-G$2)) -> 0 | AC16: =IF(H$3-H$2=0,0,(H16-H$2)/(H$3-H$2)) -> 0 | AD16: =IF(I$3-I$2=0,0,(I16-I$2)/(I$3-I$2)) -> 0 | ... AP16: =IF(U$3-U$2=0,0,(U16-U$2)/(U$3-U$2)) -> 0.25 | AQ16: =SUM(W16:AP16) -> 0.27631579
... A190: =MethodData!A187 -> Tasks: readShip(Scanner) | B190: =MethodData!B187 -> 1 | C190: =MethodData!C187 -> 0 | D190: =MethodData!D187 -> 0.8 | E190: =MethodData!E187 -> 4 | F190: =MethodData!F187 -> 0 | G190: =MethodData!G187 -> 0 | H190: =MethodData!H187 -> 7.8571 | ... U190: =MethodData!U187 -> 1 | W190: =IF(B$3-B$2=0,0,(B190-B$2)/(B$3-B$2)) -> 0.026315789 | X190: =IF(C$3-C$2=0,0,(C190-C$2)/(C$3-C$2)) -> 0 | Y190: =IF(D$3-D$2=0,0,(D190-D$2)/(D$3-D$2)) -> 0.8 | Z190: =IF(E$3-E$2=0,0,(E190-E$2)/(E$3-E$2)) -> 0.13793103 | AA190: =IF(F$3-F$2=0,0,(F190-F$2)/(F$3-F$2)) -> 0 | AB190: =IF(G$3-G$2=0,0,(G190-G$2)/(G$3-G$2)) -> 0 | AC190: =IF(H$3-H$2=0,0,(H190-H$2)/(H$3-H$2)) -> 0.078492507 | AD190: =IF(I$3-I$2=0,0,(I190-I$2)/(I$3-I$2)) -> 0.0037931822 | ... AP190: =IF(U$3-U$2=0,0,(U190-U$2)/(U$3-U$2)) -> 0.25 | AQ190: =SUM(W190:AP190) -> 2.6752729
A193: Ordenado por SOMA norm (decrescente)
A194: # | B194: Classe.Método | C194: CC norm | D194: CCM norm | E194: CDISP norm | F194: CINT norm | G194: CND norm | H194: FDP norm | I194: HD norm | J194: HEF norm | K194: HER norm | L194: HL norm | M194: HVC norm | N194: HVL norm | O194: LAA norm | P194: LND norm | Q194: LOC norm | R194: MMI norm | S194: MND norm | T194: NOAV norm | U194: NOL norm | V194: NOPM norm
A195: 1 | B195: =INDEX($A$5:$A$190,MATCH(LARGE(AQ$5:AQ$190,1),AQ$5:AQ$190,0)) -> Move: processEnemyFire(boolean) | C195: =INDEX(W$5:W$190,MATCH(LARGE(AQ$5:AQ$190,1),AQ$5:AQ$190,0)) -> 1 | D195: =INDEX(X$5:X$190,MATCH(LARGE(AQ$5:AQ$190,1),AQ$5:AQ$190,0)) -> 1 | E195: =INDEX(Y$5:Y$190,MATCH(LARGE(AQ$5:AQ$190,1),AQ$5:AQ$190,0)) -> 0.4545 | F195: =INDEX(Z$5:Z$190,MATCH(LARGE(AQ$5:AQ$190,1),AQ$5:AQ$190,0)) -> 0.75862069 | G195: =INDEX(AA$5:AA$190,MATCH(LARGE(AQ$5:AQ$190,1),AQ$5:AQ$190,0)) -> 1 | H195: =INDEX(AB$5:AB$190,MATCH(LARGE(AQ$5:AQ$190,1),AQ$5:AQ$190,0)) -> 1 | I195: =INDEX(AC$5:AC$190,MATCH(LARGE(AQ$5:AQ$190,1),AQ$5:AQ$190,0)) -> 0.76151149 | J195: =INDEX(AD$5:AD$190,MATCH(LARGE(AQ$5:AQ$190,1),AQ$5:AQ$190,0)) -> 0.98177291 | K195: =INDEX(AE$5:AE$190,MATCH(LARGE(AQ$5:AQ$190,1),AQ$5:AQ$190,0)) -> 0.98774732 | L195: =INDEX(AF$5:AF$190,MATCH(LARGE(AQ$5:AQ$190,1),AQ$5:AQ$190,0)) -> 1 | M195: =INDEX(AG$5:AG$190,MATCH(LARGE(AQ$5:AQ$190,1),AQ$5:AQ$190,0)) -> 1 | N195: =INDEX(AH$5:AH$190,MATCH(LARGE(AQ$5:AQ$190,1),AQ$5:AQ$190,0)) -> 1 | O195: =INDEX(AI$5:AI$190,MATCH(LARGE(AQ$5:AQ$190,1),AQ$5:AQ$190,0)) -> 0.2 | P195: =INDEX(AJ$5:AJ$190,MATCH(LARGE(AQ$5:AQ$190,1),AQ$5:AQ$190,0)) -> 0.33333333 | Q195: =INDEX(AK$5:AK$190,MATCH(LARGE(AQ$5:AQ$190,1),AQ$5:AQ$190,0)) -> 1 | R195: =INDEX(AL$5:AL$190,MATCH(LARGE(AQ$5:AQ$190,1),AQ$5:AQ$190,0)) -> 0.30824852 | S195: =INDEX(AM$5:AM$190,MATCH(LARGE(AQ$5:AQ$190,1),AQ$5:AQ$190,0)) -> 1 | T195: =INDEX(AN$5:AN$190,MATCH(LARGE(AQ$5:AQ$190,1),AQ$5:AQ$190,0)) -> 1 | U195: =INDEX(AO$5:AO$190,MATCH(LARGE(AQ$5:AQ$190,1),AQ$5:AQ$190,0)) -> 0.41666667 | V195: =INDEX(AP$5:AP$190,MATCH(LARGE(AQ$5:AQ$190,1),AQ$5:AQ$190,0)) -> 0.25
A196: 2 | B196: =INDEX($A$5:$A$190,MATCH(LARGE(AQ$5:AQ$190,2),AQ$5:AQ$190,0)) -> Tasks: menu() | C196: =INDEX(W$5:W$190,MATCH(LARGE(AQ$5:AQ$190,2),AQ$5:AQ$190,0)) -> 0.76315789 | D196: =INDEX(X$5:X$190,MATCH(LARGE(AQ$5:AQ$190,2),AQ$5:AQ$190,0)) -> 0.475 | E196: =INDEX(Y$5:Y$190,MATCH(LARGE(AQ$5:AQ$190,2),AQ$5:AQ$190,0)) -> 0.3125 | F196: =INDEX(Z$5:Z$190,MATCH(LARGE(AQ$5:AQ$190,2),AQ$5:AQ$190,0)) -> 1 | G196: =INDEX(AA$5:AA$190,MATCH(LARGE(AQ$5:AQ$190,2),AQ$5:AQ$190,0)) -> 0.5 | H196: =INDEX(AB$5:AB$190,MATCH(LARGE(AQ$5:AQ$190,2),AQ$5:AQ$190,0)) -> 0.4 | I196: =INDEX(AC$5:AC$190,MATCH(LARGE(AQ$5:AQ$190,2),AQ$5:AQ$190,0)) -> 1 | J196: =INDEX(AD$5:AD$190,MATCH(LARGE(AQ$5:AQ$190,2),AQ$5:AQ$190,0)) -> 1 | K196: =INDEX(AE$5:AE$190,MATCH(LARGE(AQ$5:AQ$190,2),AQ$5:AQ$190,0)) -> 1 | L196: =INDEX(AF$5:AF$190,MATCH(LARGE(AQ$5:AQ$190,2),AQ$5:AQ$190,0)) -> 0.78648649 | M196: =INDEX(AG$5:AG$190,MATCH(LARGE(AQ$5:AQ$190,2),AQ$5:AQ$190,0)) -> 0.93877551 | N196: =INDEX(AH$5:AH$190,MATCH(LARGE(AQ$5:AQ$190,2),AQ$5:AQ$190,0)) -> 0.77564904 | O196: =INDEX(AI$5:AI$190,MATCH(LARGE(AQ$5:AQ$190,2),AQ$5:AQ$190,0)) -> 0.7778 | P196: =INDEX(AJ$5:AJ$190,MATCH(LARGE(AQ$5:AQ$190,2),AQ$5:AQ$190,0)) -> 0.66666667 | Q196: =INDEX(AK$5:AK$190,MATCH(LARGE(AQ$5:AQ$190,2),AQ$5:AQ$190,0)) -> 0.92424242 | R196: =INDEX(AL$5:AL$190,MATCH(LARGE(AQ$5:AQ$190,2),AQ$5:AQ$190,0)) -> 0.32448499 | S196: =INDEX(AM$5:AM$190,MATCH(LARGE(AQ$5:AQ$190,2),AQ$5:AQ$190,0)) -> 1 | T196: =INDEX(AN$5:AN$190,MATCH(LARGE(AQ$5:AQ$190,2),AQ$5:AQ$190,0)) -> 0.77419355 | U196: =INDEX(AO$5:AO$190,MATCH(LARGE(AQ$5:AQ$190,2),AQ$5:AQ$190,0)) -> 0.16666667 | V196: =INDEX(AP$5:AP$190,MATCH(LARGE(AQ$5:AQ$190,2),AQ$5:AQ$190,0)) -> 0
A197: 3 | B197: =INDEX($A$5:$A$190,MATCH(LARGE(AQ$5:AQ$190,3),AQ$5:AQ$190,0)) -> Game: printBoard(IFleet, List<IMove>, boolean, boolean) | C197: =INDEX(W$5:W$190,MATCH(LARGE(AQ$5:AQ$190,3),AQ$5:AQ$190,0)) -> 0 | D197: =INDEX(X$5:X$190,MATCH(LARGE(AQ$5:AQ$190,3),AQ$5:AQ$190,0)) -> 0.475 | E197: =INDEX(Y$5:Y$190,MATCH(LARGE(AQ$5:AQ$190,3),AQ$5:AQ$190,0)) -> 0.5 | F197: =INDEX(Z$5:Z$190,MATCH(LARGE(AQ$5:AQ$190,3),AQ$5:AQ$190,0)) -> 0.4137931 | G197: =INDEX(AA$5:AA$190,MATCH(LARGE(AQ$5:AQ$190,3),AQ$5:AQ$190,0)) -> 0.75 | H197: =INDEX(AB$5:AB$190,MATCH(LARGE(AQ$5:AQ$190,3),AQ$5:AQ$190,0)) -> 0.2 | I197: =INDEX(AC$5:AC$190,MATCH(LARGE(AQ$5:AQ$190,3),AQ$5:AQ$190,0)) -> 0.45223077 | J197: =INDEX(AD$5:AD$190,MATCH(LARGE(AQ$5:AQ$190,3),AQ$5:AQ$190,0)) -> 0.32268903 | K197: =INDEX(AE$5:AE$190,MATCH(LARGE(AQ$5:AQ$190,3),AQ$5:AQ$190,0)) -> 0.47041205 | L197: =INDEX(AF$5:AF$190,MATCH(LARGE(AQ$5:AQ$190,3),AQ$5:AQ$190,0)) -> 0.5972973 | M197: =INDEX(AG$5:AG$190,MATCH(LARGE(AQ$5:AQ$190,3),AQ$5:AQ$190,0)) -> 0.71428571 | N197: =INDEX(AH$5:AH$190,MATCH(LARGE(AQ$5:AQ$190,3),AQ$5:AQ$190,0)) -> 0.55346405 | O197: =INDEX(AI$5:AI$190,MATCH(LARGE(AQ$5:AQ$190,3),AQ$5:AQ$190,0)) -> 0.8571 | P197: =INDEX(AJ$5:AJ$190,MATCH(LARGE(AQ$5:AQ$190,3),AQ$5:AQ$190,0)) -> 0.66666667 | Q197: =INDEX(AK$5:AK$190,MATCH(LARGE(AQ$5:AQ$190,3),AQ$5:AQ$190,0)) -> 0.53030303 | R197: =INDEX(AL$5:AL$190,MATCH(LARGE(AQ$5:AQ$190,3),AQ$5:AQ$190,0)) -> 0.39067426 | S197: =INDEX(AM$5:AM$190,MATCH(LARGE(AQ$5:AQ$190,3),AQ$5:AQ$190,0)) -> 0.5 | T197: =INDEX(AN$5:AN$190,MATCH(LARGE(AQ$5:AQ$190,3),AQ$5:AQ$190,0)) -> 0.90322581 | U197: =INDEX(AO$5:AO$190,MATCH(LARGE(AQ$5:AQ$190,3),AQ$5:AQ$190,0)) -> 1 | V197: =INDEX(AP$5:AP$190,MATCH(LARGE(AQ$5:AQ$190,3),AQ$5:AQ$190,0)) -> 1
A198: 4 | B198: =INDEX($A$5:$A$190,MATCH(LARGE(AQ$5:AQ$190,4),AQ$5:AQ$190,0)) -> PdfExporter: printMoveSection(PDDocument, PdfState, String, List<IMove>) | C198: =INDEX(W$5:W$190,MATCH(LARGE(AQ$5:AQ$190,4),AQ$5:AQ$190,0)) -> 0.23684211 | D198: =INDEX(X$5:X$190,MATCH(LARGE(AQ$5:AQ$190,4),AQ$5:AQ$190,0)) -> 0.225 | E198: =INDEX(Y$5:Y$190,MATCH(LARGE(AQ$5:AQ$190,4),AQ$5:AQ$190,0)) -> 0.35 | F198: =INDEX(Z$5:Z$190,MATCH(LARGE(AQ$5:AQ$190,4),AQ$5:AQ$190,0)) -> 0.65517241 | G198: =INDEX(AA$5:AA$190,MATCH(LARGE(AQ$5:AQ$190,4),AQ$5:AQ$190,0)) -> 0.25 | H198: =INDEX(AB$5:AB$190,MATCH(LARGE(AQ$5:AQ$190,4),AQ$5:AQ$190,0)) -> 0.8 | I198: =INDEX(AC$5:AC$190,MATCH(LARGE(AQ$5:AQ$190,4),AQ$5:AQ$190,0)) -> 0.58741259 | J198: =INDEX(AD$5:AD$190,MATCH(LARGE(AQ$5:AQ$190,4),AQ$5:AQ$190,0)) -> 0.42570052 | K198: =INDEX(AE$5:AE$190,MATCH(LARGE(AQ$5:AQ$190,4),AQ$5:AQ$190,0)) -> 0.56589218 | L198: =INDEX(AF$5:AF$190,MATCH(LARGE(AQ$5:AQ$190,4),AQ$5:AQ$190,0)) -> 0.58648649 | M198: =INDEX(AG$5:AG$190,MATCH(LARGE(AQ$5:AQ$190,4),AQ$5:AQ$190,0)) -> 0.82653061 | N198: =INDEX(AH$5:AH$190,MATCH(LARGE(AQ$5:AQ$190,4),AQ$5:AQ$190,0)) -> 0.56211635 | O198: =INDEX(AI$5:AI$190,MATCH(LARGE(AQ$5:AQ$190,4),AQ$5:AQ$190,0)) -> 0 | P198: =INDEX(AJ$5:AJ$190,MATCH(LARGE(AQ$5:AQ$190,4),AQ$5:AQ$190,0)) -> 0.66666667 | Q198: =INDEX(AK$5:AK$190,MATCH(LARGE(AQ$5:AQ$190,4),AQ$5:AQ$190,0)) -> 0.53787879 | R198: =INDEX(AL$5:AL$190,MATCH(LARGE(AQ$5:AQ$190,4),AQ$5:AQ$190,0)) -> 0.38990378 | S198: =INDEX(AM$5:AM$190,MATCH(LARGE(AQ$5:AQ$190,4),AQ$5:AQ$190,0)) -> 0.66666667 | T198: =INDEX(AN$5:AN$190,MATCH(LARGE(AQ$5:AQ$190,4),AQ$5:AQ$190,0)) -> 0.67741935 | U198: =INDEX(AO$5:AO$190,MATCH(LARGE(AQ$5:AQ$190,4),AQ$5:AQ$190,0)) -> 0.16666667 | V198: =INDEX(AP$5:AP$190,MATCH(LARGE(AQ$5:AQ$190,4),AQ$5:AQ$190,0)) -> 1
A199: 5 | B199: =INDEX($A$5:$A$190,MATCH(LARGE(AQ$5:AQ$190,5),AQ$5:AQ$190,0)) -> Game: buildMap(IFleet, List<IMove>, boolean, boolean) | C199: =INDEX(W$5:W$190,MATCH(LARGE(AQ$5:AQ$190,5),AQ$5:AQ$190,0)) -> 0.47368421 | D199: =INDEX(X$5:X$190,MATCH(LARGE(AQ$5:AQ$190,5),AQ$5:AQ$190,0)) -> 0.425 | E199: =INDEX(Y$5:Y$190,MATCH(LARGE(AQ$5:AQ$190,5),AQ$5:AQ$190,0)) -> 0.5 | F199: =INDEX(Z$5:Z$190,MATCH(LARGE(AQ$5:AQ$190,5),AQ$5:AQ$190,0)) -> 0.27586207 | G199: =INDEX(AA$5:AA$190,MATCH(LARGE(AQ$5:AQ$190,5),AQ$5:AQ$190,0)) -> 0.75 | H199: =INDEX(AB$5:AB$190,MATCH(LARGE(AQ$5:AQ$190,5),AQ$5:AQ$190,0)) -> 0 | I199: =INDEX(AC$5:AC$190,MATCH(LARGE(AQ$5:AQ$190,5),AQ$5:AQ$190,0)) -> 0.40323277 | J199: =INDEX(AD$5:AD$190,MATCH(LARGE(AQ$5:AQ$190,5),AQ$5:AQ$190,0)) -> 0.15839134 | K199: =INDEX(AE$5:AE$190,MATCH(LARGE(AQ$5:AQ$190,5),AQ$5:AQ$190,0)) -> 0.29270285 | L199: =INDEX(AF$5:AF$190,MATCH(LARGE(AQ$5:AQ$190,5),AQ$5:AQ$190,0)) -> 0.36486486 | M199: =INDEX(AG$5:AG$190,MATCH(LARGE(AQ$5:AQ$190,5),AQ$5:AQ$190,0)) -> 0.46938776 | N199: =INDEX(AH$5:AH$190,MATCH(LARGE(AQ$5:AQ$190,5),AQ$5:AQ$190,0)) -> 0.30467758 | O199: =INDEX(AI$5:AI$190,MATCH(LARGE(AQ$5:AQ$190,5),AQ$5:AQ$190,0)) -> 1 | P199: =INDEX(AJ$5:AJ$190,MATCH(LARGE(AQ$5:AQ$190,5),AQ$5:AQ$190,0)) -> 0.66666667 | Q199: =INDEX(AK$5:AK$190,MATCH(LARGE(AQ$5:AQ$190,5),AQ$5:AQ$190,0)) -> 0.32575758 | R199: =INDEX(AL$5:AL$190,MATCH(LARGE(AQ$5:AQ$190,5),AQ$5:AQ$190,0)) -> 0.45798585 | S199: =INDEX(AM$5:AM$190,MATCH(LARGE(AQ$5:AQ$190,5),AQ$5:AQ$190,0)) -> 0.83333333 | T199: =INDEX(AN$5:AN$190,MATCH(LARGE(AQ$5:AQ$190,5),AQ$5:AQ$190,0)) -> 0.70967742 | U199: =INDEX(AO$5:AO$190,MATCH(LARGE(AQ$5:AQ$190,5),AQ$5:AQ$190,0)) -> 0.75 | V199: =INDEX(AP$5:AP$190,MATCH(LARGE(AQ$5:AQ$190,5),AQ$5:AQ$190,0)) -> 1
A200: 6 | B200: =INDEX($A$5:$A$190,MATCH(LARGE(AQ$5:AQ$190,6),AQ$5:AQ$190,0)) -> BoardWindow: createBoardPanel(char[][], List<IPosition>) | C200: =INDEX(W$5:W$190,MATCH(LARGE(AQ$5:AQ$190,6),AQ$5:AQ$190,0)) -> 0.26315789 | D200: =INDEX(X$5:X$190,MATCH(LARGE(AQ$5:AQ$190,6),AQ$5:AQ$190,0)) -> 0.25 | E200: =INDEX(Y$5:Y$190,MATCH(LARGE(AQ$5:AQ$190,6),AQ$5:AQ$190,0)) -> 0.5 | F200: =INDEX(Z$5:Z$190,MATCH(LARGE(AQ$5:AQ$190,6),AQ$5:AQ$190,0)) -> 0.34482759 | G200: =INDEX(AA$5:AA$190,MATCH(LARGE(AQ$5:AQ$190,6),AQ$5:AQ$190,0)) -> 0.5 | H200: =INDEX(AB$5:AB$190,MATCH(LARGE(AQ$5:AQ$190,6),AQ$5:AQ$190,0)) -> 0.8 | I200: =INDEX(AC$5:AC$190,MATCH(LARGE(AQ$5:AQ$190,6),AQ$5:AQ$190,0)) -> 0.27472527 | J200: =INDEX(AD$5:AD$190,MATCH(LARGE(AQ$5:AQ$190,6),AQ$5:AQ$190,0)) -> 0.099562958 | K200: =INDEX(AE$5:AE$190,MATCH(LARGE(AQ$5:AQ$190,6),AQ$5:AQ$190,0)) -> 0.21483028 | L200: =INDEX(AF$5:AF$190,MATCH(LARGE(AQ$5:AQ$190,6),AQ$5:AQ$190,0)) -> 0.32162162 | M200: =INDEX(AG$5:AG$190,MATCH(LARGE(AQ$5:AQ$190,6),AQ$5:AQ$190,0)) -> 0.56122449 | N200: =INDEX(AH$5:AH$190,MATCH(LARGE(AQ$5:AQ$190,6),AQ$5:AQ$190,0)) -> 0.28110232 | O200: =INDEX(AI$5:AI$190,MATCH(LARGE(AQ$5:AQ$190,6),AQ$5:AQ$190,0)) -> 0 | P200: =INDEX(AJ$5:AJ$190,MATCH(LARGE(AQ$5:AQ$190,6),AQ$5:AQ$190,0)) -> 1 | Q200: =INDEX(AK$5:AK$190,MATCH(LARGE(AQ$5:AQ$190,6),AQ$5:AQ$190,0)) -> 0.32575758 | R200: =INDEX(AL$5:AL$190,MATCH(LARGE(AQ$5:AQ$190,6),AQ$5:AQ$190,0)) -> 0.46138515 | S200: =INDEX(AM$5:AM$190,MATCH(LARGE(AQ$5:AQ$190,6),AQ$5:AQ$190,0)) -> 1 | T200: =INDEX(AN$5:AN$190,MATCH(LARGE(AQ$5:AQ$190,6),AQ$5:AQ$190,0)) -> 0.61290323 | U200: =INDEX(AO$5:AO$190,MATCH(LARGE(AQ$5:AQ$190,6),AQ$5:AQ$190,0)) -> 0.25 | V200: =INDEX(AP$5:AP$190,MATCH(LARGE(AQ$5:AQ$190,6),AQ$5:AQ$190,0)) -> 0.5
A201: 7 | B201: =INDEX($A$5:$A$190,MATCH(LARGE(AQ$5:AQ$190,7),AQ$5:AQ$190,0)) -> Game: randomEnemyFire() | C201: =INDEX(W$5:W$190,MATCH(LARGE(AQ$5:AQ$190,7),AQ$5:AQ$190,0)) -> 0.26315789 | D201: =INDEX(X$5:X$190,MATCH(LARGE(AQ$5:AQ$190,7),AQ$5:AQ$190,0)) -> 0.25 | E201: =INDEX(Y$5:Y$190,MATCH(LARGE(AQ$5:AQ$190,7),AQ$5:AQ$190,0)) -> 0.5625 | F201: =INDEX(Z$5:Z$190,MATCH(LARGE(AQ$5:AQ$190,7),AQ$5:AQ$190,0)) -> 0.48275862 | G201: =INDEX(AA$5:AA$190,MATCH(LARGE(AQ$5:AQ$190,7),AQ$5:AQ$190,0)) -> 0.5 | H201: =INDEX(AB$5:AB$190,MATCH(LARGE(AQ$5:AQ$190,7),AQ$5:AQ$190,0)) -> 0.2 | I201: =INDEX(AC$5:AC$190,MATCH(LARGE(AQ$5:AQ$190,7),AQ$5:AQ$190,0)) -> 0.43377722 | J201: =INDEX(AD$5:AD$190,MATCH(LARGE(AQ$5:AQ$190,7),AQ$5:AQ$190,0)) -> 0.15267319 | K201: =INDEX(AE$5:AE$190,MATCH(LARGE(AQ$5:AQ$190,7),AQ$5:AQ$190,0)) -> 0.28562353 | L201: =INDEX(AF$5:AF$190,MATCH(LARGE(AQ$5:AQ$190,7),AQ$5:AQ$190,0)) -> 0.32162162 | M201: =INDEX(AG$5:AG$190,MATCH(LARGE(AQ$5:AQ$190,7),AQ$5:AQ$190,0)) -> 0.5 | N201: =INDEX(AH$5:AH$190,MATCH(LARGE(AQ$5:AQ$190,7),AQ$5:AQ$190,0)) -> 0.27299946 | O201: =INDEX(AI$5:AI$190,MATCH(LARGE(AQ$5:AQ$190,7),AQ$5:AQ$190,0)) -> 0.8 | P201: =INDEX(AJ$5:AJ$190,MATCH(LARGE(AQ$5:AQ$190,7),AQ$5:AQ$190,0)) -> 0.66666667 | Q201: =INDEX(AK$5:AK$190,MATCH(LARGE(AQ$5:AQ$190,7),AQ$5:AQ$190,0)) -> 0.34848485 | R201: =INDEX(AL$5:AL$190,MATCH(LARGE(AQ$5:AQ$190,7),AQ$5:AQ$190,0)) -> 0.45560446 | S201: =INDEX(AM$5:AM$190,MATCH(LARGE(AQ$5:AQ$190,7),AQ$5:AQ$190,0)) -> 0.5 | T201: =INDEX(AN$5:AN$190,MATCH(LARGE(AQ$5:AQ$190,7),AQ$5:AQ$190,0)) -> 0.48387097 | U201: =INDEX(AO$5:AO$190,MATCH(LARGE(AQ$5:AQ$190,7),AQ$5:AQ$190,0)) -> 0.5 | V201: =INDEX(AP$5:AP$190,MATCH(LARGE(AQ$5:AQ$190,7),AQ$5:AQ$190,0)) -> 0
A202: 8 | B202: =INDEX($A$5:$A$190,MATCH(LARGE(AQ$5:AQ$190,8),AQ$5:AQ$190,0)) -> Game: randomPlayerFire() | C202: =INDEX(W$5:W$190,MATCH(LARGE(AQ$5:AQ$190,8),AQ$5:AQ$190,0)) -> 0.26315789 | D202: =INDEX(X$5:X$190,MATCH(LARGE(AQ$5:AQ$190,8),AQ$5:AQ$190,0)) -> 0.25 | E202: =INDEX(Y$5:Y$190,MATCH(LARGE(AQ$5:AQ$190,8),AQ$5:AQ$190,0)) -> 0.5625 | F202: =INDEX(Z$5:Z$190,MATCH(LARGE(AQ$5:AQ$190,8),AQ$5:AQ$190,0)) -> 0.48275862 | G202: =INDEX(AA$5:AA$190,MATCH(LARGE(AQ$5:AQ$190,8),AQ$5:AQ$190,0)) -> 0.5 | H202: =INDEX(AB$5:AB$190,MATCH(LARGE(AQ$5:AQ$190,8),AQ$5:AQ$190,0)) -> 0.2 | I202: =INDEX(AC$5:AC$190,MATCH(LARGE(AQ$5:AQ$190,8),AQ$5:AQ$190,0)) -> 0.43377722 | J202: =INDEX(AD$5:AD$190,MATCH(LARGE(AQ$5:AQ$190,8),AQ$5:AQ$190,0)) -> 0.15267319 | K202: =INDEX(AE$5:AE$190,MATCH(LARGE(AQ$5:AQ$190,8),AQ$5:AQ$190,0)) -> 0.28562353 | L202: =INDEX(AF$5:AF$190,MATCH(LARGE(AQ$5:AQ$190,8),AQ$5:AQ$190,0)) -> 0.32162162 | M202: =INDEX(AG$5:AG$190,MATCH(LARGE(AQ$5:AQ$190,8),AQ$5:AQ$190,0)) -> 0.5 | N202: =INDEX(AH$5:AH$190,MATCH(LARGE(AQ$5:AQ$190,8),AQ$5:AQ$190,0)) -> 0.27299946 | O202: =INDEX(AI$5:AI$190,MATCH(LARGE(AQ$5:AQ$190,8),AQ$5:AQ$190,0)) -> 0.8 | P202: =INDEX(AJ$5:AJ$190,MATCH(LARGE(AQ$5:AQ$190,8),AQ$5:AQ$190,0)) -> 0.66666667 | Q202: =INDEX(AK$5:AK$190,MATCH(LARGE(AQ$5:AQ$190,8),AQ$5:AQ$190,0)) -> 0.31818182 | R202: =INDEX(AL$5:AL$190,MATCH(LARGE(AQ$5:AQ$190,8),AQ$5:AQ$190,0)) -> 0.4646028 | S202: =INDEX(AM$5:AM$190,MATCH(LARGE(AQ$5:AQ$190,8),AQ$5:AQ$190,0)) -> 0.5 | T202: =INDEX(AN$5:AN$190,MATCH(LARGE(AQ$5:AQ$190,8),AQ$5:AQ$190,0)) -> 0.48387097 | U202: =INDEX(AO$5:AO$190,MATCH(LARGE(AQ$5:AQ$190,8),AQ$5:AQ$190,0)) -> 0.5 | V202: =INDEX(AP$5:AP$190,MATCH(LARGE(AQ$5:AQ$190,8),AQ$5:AQ$190,0)) -> 0
A203: 9 | B203: =INDEX($A$5:$A$190,MATCH(LARGE(AQ$5:AQ$190,9),AQ$5:AQ$190,0)) -> Game: readEnemyFire(Scanner) | C203: =INDEX(W$5:W$190,MATCH(LARGE(AQ$5:AQ$190,9),AQ$5:AQ$190,0)) -> 0.31578947 | D203: =INDEX(X$5:X$190,MATCH(LARGE(AQ$5:AQ$190,9),AQ$5:AQ$190,0)) -> 0.325 | E203: =INDEX(Y$5:Y$190,MATCH(LARGE(AQ$5:AQ$190,9),AQ$5:AQ$190,0)) -> 0.1905 | F203: =INDEX(Z$5:Z$190,MATCH(LARGE(AQ$5:AQ$190,9),AQ$5:AQ$190,0)) -> 0.62068966 | G203: =INDEX(AA$5:AA$190,MATCH(LARGE(AQ$5:AQ$190,9),AQ$5:AQ$190,0)) -> 0.5 | H203: =INDEX(AB$5:AB$190,MATCH(LARGE(AQ$5:AQ$190,9),AQ$5:AQ$190,0)) -> 0 | I203: =INDEX(AC$5:AC$190,MATCH(LARGE(AQ$5:AQ$190,9),AQ$5:AQ$190,0)) -> 0.45854146 | J203: =INDEX(AD$5:AD$190,MATCH(LARGE(AQ$5:AQ$190,9),AQ$5:AQ$190,0)) -> 0.16552409 | K203: =INDEX(AE$5:AE$190,MATCH(LARGE(AQ$5:AQ$190,9),AQ$5:AQ$190,0)) -> 0.30141586 | L203: =INDEX(AF$5:AF$190,MATCH(LARGE(AQ$5:AQ$190,9),AQ$5:AQ$190,0)) -> 0.31891892 | M203: =INDEX(AG$5:AG$190,MATCH(LARGE(AQ$5:AQ$190,9),AQ$5:AQ$190,0)) -> 0.57142857 | N203: =INDEX(AH$5:AH$190,MATCH(LARGE(AQ$5:AQ$190,9),AQ$5:AQ$190,0)) -> 0.27999345 | O203: =INDEX(AI$5:AI$190,MATCH(LARGE(AQ$5:AQ$190,9),AQ$5:AQ$190,0)) -> 1 | P203: =INDEX(AJ$5:AJ$190,MATCH(LARGE(AQ$5:AQ$190,9),AQ$5:AQ$190,0)) -> 0.33333333 | Q203: =INDEX(AK$5:AK$190,MATCH(LARGE(AQ$5:AQ$190,9),AQ$5:AQ$190,0)) -> 0.39393939 | R203: =INDEX(AL$5:AL$190,MATCH(LARGE(AQ$5:AQ$190,9),AQ$5:AQ$190,0)) -> 0.44242486 | S203: =INDEX(AM$5:AM$190,MATCH(LARGE(AQ$5:AQ$190,9),AQ$5:AQ$190,0)) -> 0.83333333 | T203: =INDEX(AN$5:AN$190,MATCH(LARGE(AQ$5:AQ$190,9),AQ$5:AQ$190,0)) -> 0.25806452 | U203: =INDEX(AO$5:AO$190,MATCH(LARGE(AQ$5:AQ$190,9),AQ$5:AQ$190,0)) -> 0.16666667 | V203: =INDEX(AP$5:AP$190,MATCH(LARGE(AQ$5:AQ$190,9),AQ$5:AQ$190,0)) -> 0.25
A204: 10 | B204: =INDEX($A$5:$A$190,MATCH(LARGE(AQ$5:AQ$190,10),AQ$5:AQ$190,0)) -> Game: readAlienFire(Scanner) | C204: =INDEX(W$5:W$190,MATCH(LARGE(AQ$5:AQ$190,10),AQ$5:AQ$190,0)) -> 0.31578947 | D204: =INDEX(X$5:X$190,MATCH(LARGE(AQ$5:AQ$190,10),AQ$5:AQ$190,0)) -> 0.325 | E204: =INDEX(Y$5:Y$190,MATCH(LARGE(AQ$5:AQ$190,10),AQ$5:AQ$190,0)) -> 0.1905 | F204: =INDEX(Z$5:Z$190,MATCH(LARGE(AQ$5:AQ$190,10),AQ$5:AQ$190,0)) -> 0.62068966 | G204: =INDEX(AA$5:AA$190,MATCH(LARGE(AQ$5:AQ$190,10),AQ$5:AQ$190,0)) -> 0.5 | H204: =INDEX(AB$5:AB$190,MATCH(LARGE(AQ$5:AQ$190,10),AQ$5:AQ$190,0)) -> 0 | I204: =INDEX(AC$5:AC$190,MATCH(LARGE(AQ$5:AQ$190,10),AQ$5:AQ$190,0)) -> 0.45854146 | J204: =INDEX(AD$5:AD$190,MATCH(LARGE(AQ$5:AQ$190,10),AQ$5:AQ$190,0)) -> 0.16552409 | K204: =INDEX(AE$5:AE$190,MATCH(LARGE(AQ$5:AQ$190,10),AQ$5:AQ$190,0)) -> 0.30141586 | L204: =INDEX(AF$5:AF$190,MATCH(LARGE(AQ$5:AQ$190,10),AQ$5:AQ$190,0)) -> 0.31891892 | M204: =INDEX(AG$5:AG$190,MATCH(LARGE(AQ$5:AQ$190,10),AQ$5:AQ$190,0)) -> 0.57142857 | N204: =INDEX(AH$5:AH$190,MATCH(LARGE(AQ$5:AQ$190,10),AQ$5:AQ$190,0)) -> 0.27999345 | O204: =INDEX(AI$5:AI$190,MATCH(LARGE(AQ$5:AQ$190,10),AQ$5:AQ$190,0)) -> 1 | P204: =INDEX(AJ$5:AJ$190,MATCH(LARGE(AQ$5:AQ$190,10),AQ$5:AQ$190,0)) -> 0.33333333 | Q204: =INDEX(AK$5:AK$190,MATCH(LARGE(AQ$5:AQ$190,10),AQ$5:AQ$190,0)) -> 0.37878788 | R204: =INDEX(AL$5:AL$190,MATCH(LARGE(AQ$5:AQ$190,10),AQ$5:AQ$190,0)) -> 0.44630441 | S204: =INDEX(AM$5:AM$190,MATCH(LARGE(AQ$5:AQ$190,10),AQ$5:AQ$190,0)) -> 0.83333333 | T204: =INDEX(AN$5:AN$190,MATCH(LARGE(AQ$5:AQ$190,10),AQ$5:AQ$190,0)) -> 0.25806452 | U204: =INDEX(AO$5:AO$190,MATCH(LARGE(AQ$5:AQ$190,10),AQ$5:AQ$190,0)) -> 0.16666667 | V204: =INDEX(AP$5:AP$190,MATCH(LARGE(AQ$5:AQ$190,10),AQ$5:AQ$190,0)) -> 0.25
A205: 11 | B205: =INDEX($A$5:$A$190,MATCH(LARGE(AQ$5:AQ$190,11),AQ$5:AQ$190,0)) -> BoardWindow: show(char[][], char[][], List<IPosition>, List<IPosition>) | C205: =INDEX(W$5:W$190,MATCH(LARGE(AQ$5:AQ$190,11),AQ$5:AQ$190,0)) -> 0.052631579 | D205: =INDEX(X$5:X$190,MATCH(LARGE(AQ$5:AQ$190,11),AQ$5:AQ$190,0)) -> 0.025 | E205: =INDEX(Y$5:Y$190,MATCH(LARGE(AQ$5:AQ$190,11),AQ$5:AQ$190,0)) -> 0.4545 | F205: =INDEX(Z$5:Z$190,MATCH(LARGE(AQ$5:AQ$190,11),AQ$5:AQ$190,0)) -> 0.34482759 | G205: =INDEX(AA$5:AA$190,MATCH(LARGE(AQ$5:AQ$190,11),AQ$5:AQ$190,0)) -> 0.25 | H205: =INDEX(AB$5:AB$190,MATCH(LARGE(AQ$5:AQ$190,11),AQ$5:AQ$190,0)) -> 0.8 | I205: =INDEX(AC$5:AC$190,MATCH(LARGE(AQ$5:AQ$190,11),AQ$5:AQ$190,0)) -> 0.16697602 | J205: =INDEX(AD$5:AD$190,MATCH(LARGE(AQ$5:AQ$190,11),AQ$5:AQ$190,0)) -> 0.04275411 | K205: =INDEX(AE$5:AE$190,MATCH(LARGE(AQ$5:AQ$190,11),AQ$5:AQ$190,0)) -> 0.12225449 | L205: =INDEX(AF$5:AF$190,MATCH(LARGE(AQ$5:AQ$190,11),AQ$5:AQ$190,0)) -> 0.23783784 | M205: =INDEX(AG$5:AG$190,MATCH(LARGE(AQ$5:AQ$190,11),AQ$5:AQ$190,0)) -> 0.46938776 | N205: =INDEX(AH$5:AH$190,MATCH(LARGE(AQ$5:AQ$190,11),AQ$5:AQ$190,0)) -> 0.19860466 | O205: =INDEX(AI$5:AI$190,MATCH(LARGE(AQ$5:AQ$190,11),AQ$5:AQ$190,0)) -> 0.2857 | P205: =INDEX(AJ$5:AJ$190,MATCH(LARGE(AQ$5:AQ$190,11),AQ$5:AQ$190,0)) -> 0 | Q205: =INDEX(AK$5:AK$190,MATCH(LARGE(AQ$5:AQ$190,11),AQ$5:AQ$190,0)) -> 0.22727273 | R205: =INDEX(AL$5:AL$190,MATCH(LARGE(AQ$5:AQ$190,11),AQ$5:AQ$190,0)) -> 0.51023966 | S205: =INDEX(AM$5:AM$190,MATCH(LARGE(AQ$5:AQ$190,11),AQ$5:AQ$190,0)) -> 0.33333333 | T205: =INDEX(AN$5:AN$190,MATCH(LARGE(AQ$5:AQ$190,11),AQ$5:AQ$190,0)) -> 0.5483871 | U205: =INDEX(AO$5:AO$190,MATCH(LARGE(AQ$5:AQ$190,11),AQ$5:AQ$190,0)) -> 0 | V205: =INDEX(AP$5:AP$190,MATCH(LARGE(AQ$5:AQ$190,11),AQ$5:AQ$190,0)) -> 1
A206: 12 | B206: =INDEX($A$5:$A$190,MATCH(LARGE(AQ$5:AQ$190,12),AQ$5:AQ$190,0)) -> PdfExporter: exportGameReport(IGame, String) | C206: =INDEX(W$5:W$190,MATCH(LARGE(AQ$5:AQ$190,12),AQ$5:AQ$190,0)) -> 0.052631579 | D206: =INDEX(X$5:X$190,MATCH(LARGE(AQ$5:AQ$190,12),AQ$5:AQ$190,0)) -> 0.025 | E206: =INDEX(Y$5:Y$190,MATCH(LARGE(AQ$5:AQ$190,12),AQ$5:AQ$190,0)) -> 0.2632 | F206: =INDEX(Z$5:Z$190,MATCH(LARGE(AQ$5:AQ$190,12),AQ$5:AQ$190,0)) -> 0.62068966 | G206: =INDEX(AA$5:AA$190,MATCH(LARGE(AQ$5:AQ$190,12),AQ$5:AQ$190,0)) -> 0 | H206: =INDEX(AB$5:AB$190,MATCH(LARGE(AQ$5:AQ$190,12),AQ$5:AQ$190,0)) -> 1 | I206: =INDEX(AC$5:AC$190,MATCH(LARGE(AQ$5:AQ$190,12),AQ$5:AQ$190,0)) -> 0.28971029 | J206: =INDEX(AD$5:AD$190,MATCH(LARGE(AQ$5:AQ$190,12),AQ$5:AQ$190,0)) -> 0.083309085 | K206: =INDEX(AE$5:AE$190,MATCH(LARGE(AQ$5:AQ$190,12),AQ$5:AQ$190,0)) -> 0.19077873 | L206: =INDEX(AF$5:AF$190,MATCH(LARGE(AQ$5:AQ$190,12),AQ$5:AQ$190,0)) -> 0.25405405 | M206: =INDEX(AG$5:AG$190,MATCH(LARGE(AQ$5:AQ$190,12),AQ$5:AQ$190,0)) -> 0.57142857 | N206: =INDEX(AH$5:AH$190,MATCH(LARGE(AQ$5:AQ$190,12),AQ$5:AQ$190,0)) -> 0.22304564 | O206: =INDEX(AI$5:AI$190,MATCH(LARGE(AQ$5:AQ$190,12),AQ$5:AQ$190,0)) -> 0 | P206: =INDEX(AJ$5:AJ$190,MATCH(LARGE(AQ$5:AQ$190,12),AQ$5:AQ$190,0)) -> 0 | Q206: =INDEX(AK$5:AK$190,MATCH(LARGE(AQ$5:AQ$190,12),AQ$5:AQ$190,0)) -> 0.25757576 | R206: =INDEX(AL$5:AL$190,MATCH(LARGE(AQ$5:AQ$190,12),AQ$5:AQ$190,0)) -> 0.49422349 | S206: =INDEX(AM$5:AM$190,MATCH(LARGE(AQ$5:AQ$190,12),AQ$5:AQ$190,0)) -> 0.33333333 | T206: =INDEX(AN$5:AN$190,MATCH(LARGE(AQ$5:AQ$190,12),AQ$5:AQ$190,0)) -> 0.4516129 | U206: =INDEX(AO$5:AO$190,MATCH(LARGE(AQ$5:AQ$190,12),AQ$5:AQ$190,0)) -> 0 | V206: =INDEX(AP$5:AP$190,MATCH(LARGE(AQ$5:AQ$190,12),AQ$5:AQ$190,0)) -> 0.5
A207: 13 | B207: =INDEX($A$5:$A$190,MATCH(LARGE(AQ$5:AQ$190,13),AQ$5:AQ$190,0)) -> Game: fireSingleShot(IPosition, boolean) | C207: =INDEX(W$5:W$190,MATCH(LARGE(AQ$5:AQ$190,13),AQ$5:AQ$190,0)) -> 0.15789474 | D207: =INDEX(X$5:X$190,MATCH(LARGE(AQ$5:AQ$190,13),AQ$5:AQ$190,0)) -> 0.15 | E207: =INDEX(Y$5:Y$190,MATCH(LARGE(AQ$5:AQ$190,13),AQ$5:AQ$190,0)) -> 0.6 | F207: =INDEX(Z$5:Z$190,MATCH(LARGE(AQ$5:AQ$190,13),AQ$5:AQ$190,0)) -> 0.13793103 | G207: =INDEX(AA$5:AA$190,MATCH(LARGE(AQ$5:AQ$190,13),AQ$5:AQ$190,0)) -> 0.5 | H207: =INDEX(AB$5:AB$190,MATCH(LARGE(AQ$5:AQ$190,13),AQ$5:AQ$190,0)) -> 0 | I207: =INDEX(AC$5:AC$190,MATCH(LARGE(AQ$5:AQ$190,13),AQ$5:AQ$190,0)) -> 0.24702597 | J207: =INDEX(AD$5:AD$190,MATCH(LARGE(AQ$5:AQ$190,13),AQ$5:AQ$190,0)) -> 0.040035985 | K207: =INDEX(AE$5:AE$190,MATCH(LARGE(AQ$5:AQ$190,13),AQ$5:AQ$190,0)) -> 0.11699038 | L207: =INDEX(AF$5:AF$190,MATCH(LARGE(AQ$5:AQ$190,13),AQ$5:AQ$190,0)) -> 0.17297297 | M207: =INDEX(AG$5:AG$190,MATCH(LARGE(AQ$5:AQ$190,13),AQ$5:AQ$190,0)) -> 0.28571429 | N207: =INDEX(AH$5:AH$190,MATCH(LARGE(AQ$5:AQ$190,13),AQ$5:AQ$190,0)) -> 0.1257111 | O207: =INDEX(AI$5:AI$190,MATCH(LARGE(AQ$5:AQ$190,13),AQ$5:AQ$190,0)) -> 1 | P207: =INDEX(AJ$5:AJ$190,MATCH(LARGE(AQ$5:AQ$190,13),AQ$5:AQ$190,0)) -> 0 | Q207: =INDEX(AK$5:AK$190,MATCH(LARGE(AQ$5:AQ$190,13),AQ$5:AQ$190,0)) -> 0.25 | R207: =INDEX(AL$5:AL$190,MATCH(LARGE(AQ$5:AQ$190,13),AQ$5:AQ$190,0)) -> 0.51385403 | S207: =INDEX(AM$5:AM$190,MATCH(LARGE(AQ$5:AQ$190,13),AQ$5:AQ$190,0)) -> 0.5 | T207: =INDEX(AN$5:AN$190,MATCH(LARGE(AQ$5:AQ$190,13),AQ$5:AQ$190,0)) -> 0.25806452 | U207: =INDEX(AO$5:AO$190,MATCH(LARGE(AQ$5:AQ$190,13),AQ$5:AQ$190,0)) -> 0 | V207: =INDEX(AP$5:AP$190,MATCH(LARGE(AQ$5:AQ$190,13),AQ$5:AQ$190,0)) -> 0.5
A208: 14 | B208: =INDEX($A$5:$A$190,MATCH(LARGE(AQ$5:AQ$190,14),AQ$5:AQ$190,0)) -> Scoreboard: displayScoreboard(int) | C208: =INDEX(W$5:W$190,MATCH(LARGE(AQ$5:AQ$190,14),AQ$5:AQ$190,0)) -> 0.13157895 | D208: =INDEX(X$5:X$190,MATCH(LARGE(AQ$5:AQ$190,14),AQ$5:AQ$190,0)) -> 0.125 | E208: =INDEX(Y$5:Y$190,MATCH(LARGE(AQ$5:AQ$190,14),AQ$5:AQ$190,0)) -> 0.5714 | F208: =INDEX(Z$5:Z$190,MATCH(LARGE(AQ$5:AQ$190,14),AQ$5:AQ$190,0)) -> 0.44827586 | G208: =INDEX(AA$5:AA$190,MATCH(LARGE(AQ$5:AQ$190,14),AQ$5:AQ$190,0)) -> 0.25 | H208: =INDEX(AB$5:AB$190,MATCH(LARGE(AQ$5:AQ$190,14),AQ$5:AQ$190,0)) -> 0.4 | I208: =INDEX(AC$5:AC$190,MATCH(LARGE(AQ$5:AQ$190,14),AQ$5:AQ$190,0)) -> 0.2013986 | J208: =INDEX(AD$5:AD$190,MATCH(LARGE(AQ$5:AQ$190,14),AQ$5:AQ$190,0)) -> 0.048249299 | K208: =INDEX(AE$5:AE$190,MATCH(LARGE(AQ$5:AQ$190,14),AQ$5:AQ$190,0)) -> 0.13251044 | L208: =INDEX(AF$5:AF$190,MATCH(LARGE(AQ$5:AQ$190,14),AQ$5:AQ$190,0)) -> 0.21891892 | M208: =INDEX(AG$5:AG$190,MATCH(LARGE(AQ$5:AQ$190,14),AQ$5:AQ$190,0)) -> 0.5 | N208: =INDEX(AH$5:AH$190,MATCH(LARGE(AQ$5:AQ$190,14),AQ$5:AQ$190,0)) -> 0.18582315 | O208: =INDEX(AI$5:AI$190,MATCH(LARGE(AQ$5:AQ$190,14),AQ$5:AQ$190,0)) -> 0.3333 | P208: =INDEX(AJ$5:AJ$190,MATCH(LARGE(AQ$5:AQ$190,14),AQ$5:AQ$190,0)) -> 0 | Q208: =INDEX(AK$5:AK$190,MATCH(LARGE(AQ$5:AQ$190,14),AQ$5:AQ$190,0)) -> 0.33333333 | R208: =INDEX(AL$5:AL$190,MATCH(LARGE(AQ$5:AQ$190,14),AQ$5:AQ$190,0)) -> 0.47323573 | S208: =INDEX(AM$5:AM$190,MATCH(LARGE(AQ$5:AQ$190,14),AQ$5:AQ$190,0)) -> 0.33333333 | T208: =INDEX(AN$5:AN$190,MATCH(LARGE(AQ$5:AQ$190,14),AQ$5:AQ$190,0)) -> 0.41935484 | U208: =INDEX(AO$5:AO$190,MATCH(LARGE(AQ$5:AQ$190,14),AQ$5:AQ$190,0)) -> 0 | V208: =INDEX(AP$5:AP$190,MATCH(LARGE(AQ$5:AQ$190,14),AQ$5:AQ$190,0)) -> 0.25
